Workbook

Sheet FeederNames
A1: Management Console Name | B1: Customer Name | D1: SourceID for KVA Demand | G1: Source ID for Avg KVA
B2: LT_Room.Main_Incomer
B3: LT_Room.LT_Panel_Main_Incomer | C3: LT_Room.Main_Incomer | D3: LT_Room.LT_Panel_Main_Incomer | E3: LT_Room.Shop_Floor_and_Utility_Lighting | F3: LT_Room.Shaft | G3: LT_Room.Transmission_Flange | H3: LT_Room.APFC_Incomer | I3: LT_Room.Wheel_Flange | J3: LT_Room.Office_Building | K3: LT_Room.Shaft_EFD | L3: LT_Room.Flange_Line_EFD | M3: LT_Room.Fire_Hydrant | N3: LT_Room.Lighting_DB | O3: LT_Room.Utility_Incomer | P3: LT_Room.Cooling_Tower | Q3: LT_Room.Shop_Floor_Office_Lighting_AC | R3: LT_Room.Compressor_75KW | S3: LT_Room.Compressor_55KW | T3: LT_Room.HTP | U3: LT_Room.ETP | V3: Shaft.Shaft_Incomer | W3: Shaft.Shaft_Uno_1 | X3: Shaft.Shaft_Uno_2 | Y3: Shaft.Rolling | Z3: Shaft.Robot_892 | AA3: Shaft.Washing_Machine | AB3: Shaft.Robot_891 | AC3: Shaft.Shaft_MPI | AD3: Shaft.Shaft_Assembly | AE3: Spider.Spider_Incomer | AF3: Spider.Spider_Gantry | AG3: Spider.Turning | AH3: Spider.Broching | AI3: Spider.Centerless_Grinding | AJ3: Spider.Smarter | AK3: Wheel_Flange.Wheel_Flange_Incomer | AL3: Wheel_Flange.Thread_Rolling | AM3: Wheel_Flange.Robot_893 | AN3: Wheel_Flange.OD_Griding | AO3: Wheel_Flange.Gantry | AP3: Wheel_Flange.Rolling | AQ3: Wheel_Flange.Keyway_Milling | AR3: Wheel_Flange.Robot_894 | AS3: Wheel_Flange.Turning | AT3: Transmission_Flange.Transmission_Flange_Incomer | AU3: Transmission_Flange.Turning_Machine | AV3: Transmission_Flange.Gantry | AW3: Transmission_Flange.Smarter | AX3: Transmission_Flange.MPI | AY3: Transmission_Flange.UPS_R_and_D_Building | AZ3: Transmission_Flange.Gainding_Machine | BA3: Transmission_Flange.Broching_Machine | BB3: Power_DB.Power_DB_Incomer | BC3: Transmission_Flange.Final_Washing_Machine | BD3: Power_DB.ToolRoom_Store_DB_Box | BE3: Power_DB.Security_Gate | BF3: Spare-1 | BG3: Spare-2 | BH3: Spare-3 | BI3: Spare-4 | BJ3: Spare-5 | JA3: Q3_PCC1.4F4_Office_Panel | JB3: Q3_PCC1.5F2_PDB1_Main_RPDB | JC3: Q3_PCC1.5F1_SPARE1 | JD3: Q3_PCC1.5F3_SPARE2 | JE3: Q3_PCC1.5F4_SPARE3 | JF3: Q3_PCC1.6F3_PDB4 | JG3: Q3_PCC1.6F4_MLDB | JH3: Q3_PCC1.7F3_Server_Room | JI3: Q3_PCC1.7F4_PH_II_Utility_Panel | JJ3: Q3_PCC1.4F1_STP | JK3: Q3_PCC1.6F2_SPARE4 | JL3: Q3_Tech.1F2_UPS_Incomer_DB3 | JM3: Q3_Tech.1F1_UPS1 | JN3: Q3_Tech.1F2_UPS2 | JO3: Q3_Tech.1F3_UPS3 | JP3: Q3_Tech.1F5_UPS_Incomer_DB1 | JQ3: Q3_Tech.2F1_LGF_LTG_27A | JR3: Q3_Tech.2F2_UGF_LTG_27A | JS3: Q3_Tech.2F3_SPARE1 | JT3: Q3_Tech.2F4_SPARE2 | JU3: Q3_Tech.2F5_UPS_Incomer_DB3 | JV3: Q3_Tech.1F2_PDB1_Main_RPDB | JW3: Q3_Tech.1F6_PDB2 | JX3: Q3_Tech.1F2_MLDB_MEZZ1_Technic_RM | JY3: Q3_Tech.2F3_MLDB1 | JZ3: Q3_Tech.1F2_PDB3_HVAC_Panel | KA3: PH2_Utility.1F2_Incomer_Panel | KB3: PH2_Utility.2F1_Security_Cabin3 | KC3: PH2_Utility.2F2_Security_Cabin4 | KD3: PH2_Utility.2F3_Security_Cabin5 | KE3: PH2_Utility.2F4_SPARE1 | KF3: PH2_Utility.2F5_MDB4 | KG3: PH2_Utility.2F6_SPARE2 | KH3: Q3_Office.1F2_Office_Panel_IC | KI3: Q3_Office.2F3_Incomer_for_RPDBS | KJ3: Q3_Office.3F5_MZZ2_Office_Area | KK3: Q3_Office.3F4_MZZ1_Office_Area | KL3: Q3_Office.4F2_SPARE1 | KM3: Q3_Office.4F3_UPS_40KW | KN3: Q3_Office.4F4_SPARE2 | KO3: Q3_Office.4F5_SPARE3 | KP3: Q3_Office.3F1_Incomer_for_LDBS | KQ3: Q3_Office.3F2_Lift | KR3: Q3_Office.3F3_LGF_Office | KS3: ION.7650 | KT3: WHP_PCC1.1F3_PCC1_IC | KU3: WHP_PCC1.2F3_PCC2 | KV3: WHP_PCC1.2F4_HVAC | KW3: WHP_PCC1.3F3_FIRE_FTG | KX3: WHP_PCC1.3F4_SPARE | KY3: WHP_PCC2.1F2_PCC2_IC | KZ3: WHP_PCC2.1F5_MLDB1 | LA3: WHP_PCC2.1F6_UPS_IC | LB3: WHP_PCC2.2F7_MLDB2 | LC3: WHP_PCC2.2F8_MRPDB | LD3: WHP_PCC2.3F8_SPARE | LE3: WHP_UPS_OG.1F1_IC1_UPS1 | LF3: WHP_UPS_OG.1F2_IC2_UPS2 | LG3: WHP_UPS_OG.1F3_IC3_UPS3 | LH3: WHP_UPS_IC.1F2_UPS_IC | LI3: WHP_MELDB_1.1F2_IC_MELDB1 | LJ3: WHP_MLDB1.1F1_IC_MLDB1 | LK3: WHP_MRPDB.1F2_IC_MRPDB | LL3: WHP_HVAC.1F2_IC_HVAC | LM3: KIOSK.QIII_RMU | LN3: KIOSK.QI_QII_RMU | LO3: KIOSK.PS_RMU
B4: LT_Room.Shop_Floor_and_Utility_Lighting
B5: LT_Room.Shaft
B6: LT_Room.Transmission_Flange
B7: LT_Room.APFC_Incomer
B8: LT_Room.Wheel_Flange
B9: LT_Room.Office_Building
B10: LT_Room.Shaft_EFD
B11: LT_Room.Flange_Line_EFD
B12: LT_Room.Fire_Hydrant
B13: LT_Room.Lighting_DB
B14: LT_Room.Utility_Incomer
B15: LT_Room.Cooling_Tower
... B61: Spare-5
A62: Utility_Panel.Scrap_Yard
A63: Utility_Panel.STP
A64: Utility_Panel.Compressor
A65: Compressor.Incomer
A66: Compressor.1
A67: Compressor.2
A68: Compressor.Spare
A69: A_PDB01.Incomer
A70: Compressor.3
A71: M_UPS_Panel.Incomer
A72: M_UPS_Panel.Incomer2
A73: A_MPDB01.Incomer
... A204: C_HVLS_Panel.Incomer

Sheet Production data
A1: Feeder Description | B1: 45901 | C1: 45902 | D1: 45903 | E1: 45904 | F1: 45905 | G1: 45906 | H1: 45907 | I1: 45908 | J1: 45909 | K1: 45910 | L1: 45911 | M1: 45912 | N1: 45913 | O1: 45914 | P1: 45915 | Q1: 45916 | R1: 45917 | S1: 45918 | T1: 45919 | U1: 45920 | V1: 45921 | W1: 45922 | X1: 45923 | Y1: 45924 | Z1: 45925 | AA1: 45926 | AB1: 45927 | AC1: 45928 | AD1: 45929 | AE1: 45930 | AF1: 45931
A2: FLANGE EFD | C2: 818 | D2: 1807 | E2: 2015 | F2: 1806 | H2: 1310 | I2: 1189 | J2: 1740 | K2: 929 | L2: 1595 | M2: 1495 | N2: 1517 | O2: 770 | P2: 2011 | Q2: 1859 | R2: 1800 | S2: 1362 | T2: 1683 | U2: 1535 | V2: 799 | W2: 1820 | X2: 1481 | Y2: 1654 | Z2: 2012 | AA2: 1754 | AB2: 1893 | AC2: 1442 | AD2: 1553 | AE2: 253
A3: WHEEL FLANGE OD GRINDING | C3: 331 | D3: 1041 | E3: 955 | F3: 396 | H3: 771 | I3: 537 | J3: 1075 | K3: 466 | L3: 881 | M3: 766 | N3: 726 | O3: 300 | P3: 876 | Q3: 978 | R3: 1037 | S3: 816 | T3: 0 | U3: 881 | V3: 369 | W3: 495 | X3: 704 | Y3: 955 | Z3: 248 | AA3: 510 | AB3: 706 | AC3: 652 | AD3: 932 | AE3: 154
A4: TF OD GRINDING
A5: SHAFT CNC | C5: 623 | D5: 370 | E5: 580 | F5: 300 | H5: 448 | I5: 400 | J5: 347 | K5: 473 | L5: 432 | M5: 550 | N5: 670 | O5: 260 | P5: 711 | Q5: 749 | R5: 192 | S5: 560 | T5: 804 | U5: 821 | V5: 0 | W5: 635 | X5: 271 | Y5: 150 | Z5: 130 | AA5: 442 | AB5: 550 | AC5: 130 | AD5: 740 | AE5: 340
A6: SHAFT EFD | C6: 1028 | D6: 672 | E6: 796 | F6: 646 | H6: 504 | I6: 726 | J6: 796 | K6: 472 | L6: 554 | M6: 392 | N6: 1202 | O6: 366 | P6: 541 | Q6: 1123 | R6: 652 | S6: 1002 | T6: 1092 | U6: 462 | V6: 0 | W6: 1068 | X6: 487 | Y6: 1376 | Z6: 576 | AA6: 622 | AB6: 710 | AC6: 1022 | AD6: 599 | AE6: 774
A7: SPIDER TURNING | C7: 690 | D7: 805 | E7: 700 | F7: 756 | H7: 756 | I7: 743 | J7: 770 | K7: 761 | L7: 847 | M7: 789 | N7: 803 | O7: 0 | P7: 783 | Q7: 814 | R7: 755 | S7: 857 | T7: 777 | U7: 651 | V7: 0 | W7: 651 | X7: 676 | Y7: 798 | Z7: 620 | AA7: 710 | AB7: 482 | AC7: 0 | AD7: 620 | AE7: 300
A8: SPIDER TURNING SMARTER | C8: 665 | D8: 706 | E8: 732 | F8: 946 | H8: 865 | I8: 884 | J8: 880 | K8: 367 | L8: 584 | M8: 822 | N8: 430 | O8: 0 | P8: 848 | Q8: 782 | R8: 922 | S8: 808 | T8: 692 | U8: 536 | V8: 0 | W8: 507 | X8: 671 | Y8: 796 | Z8: 619 | AA8: 710 | AB8: 480 | AC8: 0 | AD8: 643 | AE8: 300
A9: SPIDER BROACHING | C9: 230 | D9: 813 | E9: 1030 | F9: 915 | H9: 985 | I9: 850 | J9: 900 | K9: 840 | L9: 1013 | M9: 470 | N9: 0 | O9: 0 | P9: 0 | Q9: 0 | R9: 0 | S9: 315 | T9: 430 | U9: 80 | V9: 0 | W9: 80 | X9: 602 | Y9: 130 | Z9: 0 | AA9: 0 | AB9: 0 | AC9: 0 | AD9: 0 | AE9: 0
A10: SPIDER CENTERLESS GRINDING-1 | C10: 698 | D10: 1133 | E10: 1139 | F10: 1169 | H10: 0 | I10: 433 | J10: 1200 | K10: 1170 | L10: 1068 | M10: 1124 | N10: 1280 | O10: 0 | P10: 1106 | Q10: 1140 | R10: 1225 | S10: 1190 | T10: 675 | U10: 890 | V10: 425 | W10: 968 | X10: 1255 | Y10: 1271 | Z10: 1191 | AA10: 1415 | AB10: 1305 | AC10: 1010 | AD10: 1353 | AE10: 210
A11: SPIDER CENTERLESS GRINDING-2 | C11: 991 | D11: 1010 | E11: 1005 | F11: 603 | H11: 0 | I11: 0 | J11: 1074 | K11: 880 | L11: 1068 | M11: 520 | N11: 846 | O11: 567 | P11: 1011 | Q11: 1099 | R11: 1105 | S11: 1091 | T11: 0 | U11: 751 | V11: 275 | W11: 865 | X11: 1169 | Y11: 1267 | Z11: 1125 | AA11: 1395 | AB11: 1371 | AC11: 782 | AD11: 970 | AE11: 0
A12: WHEEL FLANGE THREAD ROLLING | C12: 700 | D12: 742 | E12: 835 | F12: 1223 | H12: 1125 | I12: 1000 | J12: 497 | K12: 436 | L12: 214 | M12: 380 | N12: 1208 | O12: 450 | P12: 543 | Q12: 1100 | R12: 440 | S12: 374 | T12: 0 | U12: 1155 | V12: 264 | W12: 820 | X12: 1440 | Y12: 890 | Z12: 0 | AA12: 700 | AB12: 980 | AC12: 0 | AD12: 995 | AE12: 0
A13: WHEEL FLANGE TURNING | C13: 0 | D13: 0 | E13: 0 | F13: 0 | H13: 0 | I13: 0 | J13: 0 | K13: 0 | L13: 0 | M13: 0 | N13: 0 | O13: 0 | P13: 0 | Q13: 0 | R13: 0 | S13: 0 | T13: 0 | U13: 0 | V13: 0 | W13: 0 | X13: 0 | Y13: 0 | Z13: 0 | AA13: 0 | AB13: 0 | AC13: 0 | AD13: 0 | AE13: 0
A14: TF TURNING TT | C14: 0 | D14: 0 | E14: 0 | F14: 0 | H14: 0 | I14: 175 | J14: 360 | K14: 246 | L14: 0 | M14: 619 | N14: 0 | O14: 0 | P14: 0 | Q14: 0 | R14: 593 | S14: 400 | T14: 460 | U14: 204 | V14: 0 | W14: 105 | X14: 213 | Y14: 0 | Z14: 0 | AA14: 0 | AB14: 0 | AC14: 0 | AD14: 0 | AE14: 0
A15: ASSEMBLY LINE | C15: 0 | D15: 597 | E15: 628 | F15: 913 | H15: 523 | I15: 0 | J15: 1004 | K15: 1157 | L15: 0 | M15: 1046 | N15: 0 | O15: 744 | P15: 1089 | Q15: 1083 | R15: 960 | S15: 958 | T15: 345 | U15: 801 | V15: 0 | W15: 1235 | X15: 1167 | Y15: 925 | Z15: 400 | AA15: 517 | AB15: 1125 | AC15: 1063 | AD15: 764 | AE15: 684
A16: SHAFT RACK ROLLING | C16: 1159 | D16: 918 | E16: 1274 | F16: 1216 | H16: 1170 | I16: 1055 | J16: 567 | K16: 589 | L16: 800 | M16: 555 | N16: 858 | O16: 512 | P16: 632 | Q16: 1264 | R16: 1055 | S16: 850 | T16: 960 | U16: 440 | V16: 0 | W16: 1236 | X16: 841 | Y16: 791 | Z16: 568 | AA16: 846 | AB16: 710 | AC16: 936 | AD16: 617 | AE16: 692

Sheet Sep 2025
F1: ='Production data'!B1 -> 45901 | J1: ='Production data'!C1 -> 45902 | N1: ='Production data'!D1 -> 45903 | R1: ='Production data'!E1 -> 45904 | V1: ='Production data'!F1 -> 45905 | Z1: ='Production data'!G1 -> 45906 | AD1: ='Production data'!H1 -> 45907 | AH1: ='Production data'!I1 -> 45908 | AL1: ='Production data'!J1 -> 45909 | AP1: ='Production data'!K1 -> 45910 | AT1: ='Production data'!L1 -> 45911 | AX1: ='Production data'!M1 -> 45912 | BB1: ='Production data'!N1 -> 45913 | BF1: ='Production data'!O1 -> 45914 | BJ1: ='Production data'!P1 -> 45915 | BN1: ='Production data'!Q1 -> 45916 | BR1: ='Production data'!R1 -> 45917 | BV1: ='Production data'!S1 -> 45918 | BZ1: ='Production data'!T1 -> 45919 | CD1: ='Production data'!U1 -> 45920 | CH1: ='Production data'!V1 -> 45921 | CL1: ='Production data'!W1 -> 45922 | CP1: ='Production data'!X1 -> 45923 | CT1: ='Production data'!Y1 -> 45924 | CX1: ='Production data'!Z1 -> 45925 | DB1: ='Production data'!AA1 -> 45926 | DF1: ='Production data'!AB1 -> 45927 | DJ1: ='Production data'!AC1 -> 45928 | DN1: ='Production data'!AD1 -> 45929 | DR1: ='Production data'!AE1 -> 45930 | DV1: ='Production data'!AF1 -> 45931 | DZ1: Total
C2: Sr No | D2: Feeder Description | E2: Group | F2: KWH | G2: Prod. | H2: KWH\ Pc | I2: Cost/ Pc | J2: KWH | K2: Prod. | L2: KWH\ Pc | M2: Cost/ Pc | N2: KWH | O2: Prod. | P2: KWH\ Pc | Q2: Cost/ Pc | R2: KWH | S2: Prod. | T2: KWH\ Pc | U2: Cost/ Pc | V2: KWH | W2: Prod. | X2: KWH\ Pc | Y2: Cost/ Pc | Z2: KWH | AA2: Prod. | AB2: KWH\ Pc | AC2: Cost/ Pc | AD2: KWH | AE2: Prod. | AF2: KWH\ Pc | AG2: Cost/ Pc | AH2: KWH | AI2: Prod. | AJ2: KWH\ Pc | AK2: Cost/ Pc | AL2: KWH | AM2: Prod. | AN2: KWH\ Pc | AO2: Cost/ Pc | AP2: KWH | AQ2: Prod. | AR2: KWH\ Pc | AS2: Cost/ Pc | AT2: KWH | AU2: Prod. | AV2: KWH\ Pc | AW2: Cost/ Pc | AX2: KWH | AY2: Prod. | AZ2: KWH\ Pc | BA2: Cost/ Pc | BB2: KWH | BC2: Prod. | BD2: KWH\ Pc | BE2: Cost/ Pc | BF2: KWH | BG2: Prod. | BH2: KWH\ Pc | BI2: Cost/ Pc | BJ2: KWH | BK2: Prod. | BL2: KWH\ Pc | BM2: Cost/ Pc | BN2: KWH | BO2: Prod. | BP2: KWH\ Pc | BQ2: Cost/ Pc | BR2: KWH | BS2: Prod. | BT2: KWH\ Pc | BU2: Cost/ Pc | BV2: KWH | BW2: Prod. | BX2: KWH\ Pc | BY2: Cost/ Pc | BZ2: KWH | CA2: Prod. | CB2: KWH\ Pc | CC2: Cost/ Pc | CD2: KWH | CE2: Prod. | CF2: KWH\ Pc | CG2: Cost/ Pc | CH2: KWH | CI2: Prod. | CJ2: KWH\ Pc | CK2: Cost/ Pc | CL2: KWH | CM2: Prod. | CN2: KWH\ Pc | CO2: Cost/ Pc | CP2: KWH | CQ2: Prod. | CR2: KWH\ Pc | CS2: Cost/ Pc | CT2: KWH | CU2: Prod. | CV2: KWH\ Pc | CW2: Cost/ Pc | CX2: KWH | CY2: Prod. | CZ2: KWH\ Pc | DA2: Cost/ Pc | DB2: KWH | DC2: Prod. | DD2: KWH\ Pc | DE2: Cost/ Pc | DF2: KWH | DG2: Prod. | DH2: KWH\ Pc | DI2: Cost/ Pc | DJ2: KWH | DK2: Prod. | DL2: KWH\ Pc | DM2: Cost/ Pc | DN2: KWH | DO2: Prod. | DP2: KWH\ Pc | DQ2: Cost/ Pc | DR2: KWH | DS2: Prod. | DT2: KWH\ Pc | DU2: Cost/ Pc | DV2: KWH | DW2: Prod. | DX2: KWH\ Pc | DY2: Cost/ Pc | DZ2: KWH | EA2: Prod. | EB2: KWH\ Pc | EC2: Cost/ Pc
C3: 10 | D3: LT ROOM FLANGE EFD | F3: 3 | G3: ='Production data'!B2 -> 0 | H3: =IF((G3=0),0,F3/G3) -> 0 | I3: =H3*9.04 -> 0 | J3: 649 | K3: ='Production data'!C2 -> 818 | L3: =IF((K3=0),0,J3/K3) -> 0.79339853 | M3: =L3*9.04 -> 7.1723227 | N3: 888 | O3: ='Production data'!D2 -> 1807 | P3: =IF((O3=0),0,N3/O3) -> 0.49142225 | Q3: =P3*9.04 -> 4.4424571 | R3: 927 | S3: ='Production data'!E2 -> 2015 | T3: =IF((S3=0),0,R3/S3) -> 0.46004963 | U3: =T3*9.04 -> 4.1588486 | V3: 912 | W3: ='Production data'!F2 -> 1806 | X3: =IF((W3=0),0,V3/W3) -> 0.50498339 | Y3: =X3*9.04 -> 4.5650498 | Z3: 49 | AA3: ='Production data'!G2 -> 0 | AB3: =IF((AA3=0),0,Z3/AA3) -> 0 | AC3: =AB3*9.04 -> 0 | AD3: 813 | AE3: ='Production data'!H2 -> 1310 | AF3: =IF((AE3=0),0,AD3/AE3) -> 0.62061069 | AG3: =AF3*9.04 -> 5.6103206 | AH3: 786 | AI3: ='Production data'!I2 -> 1189 | AJ3: =IF((AI3=0),0,AH3/AI3) -> 0.66105971 | AK3: =AJ3*9.04 -> 5.9759798 | AL3: 882 | AM3: ='Production data'!J2 -> 1740 | AN3: =IF((AM3=0),0,AL3/AM3) -> 0.50689655 | AO3: =AN3*9.04 -> 4.5823448 | AP3: 545 | AQ3: ='Production data'!K2 -> 929 | AR3: =IF((AQ3=0),0,AP3/AQ3) -> 0.58665231 | AS3: =AR3*9.04 -> 5.3033369 | AT3: 921 | AU3: ='Production data'!L2 -> 1595 | AV3: =IF((AU3=0),0,AT3/AU3) -> 0.57742947 | AW3: =AV3*9.04 -> 5.2199624 | AX3: 885 | AY3: ='Production data'!M2 -> 1495 | AZ3: =IF((AY3=0),0,AX3/AY3) -> 0.59197324 | BA3: =AZ3*9.04 -> 5.3514381 | BB3: 820 | BC3: ='Production data'!N2 -> 1517 | BD3: =IF((BC3=0),0,BB3/BC3) -> 0.54054054 | BE3: =BD3*9.04 -> 4.8864865 | BF3: 473 | BG3: ='Production data'!O2 -> 770 | BH3: =IF((BG3=0),0,BF3/BG3) -> 0.61428571 | BI3: =BH3*9.04 -> 5.5531429 | BJ3: 949 | BK3: ='Production data'!P2 -> 2011 | BL3: =IF((BK3=0),0,BJ3/BK3) -> 0.47190453 | BM3: =BL3*9.04 -> 4.2660169 | BN3: 939 | BO3: ='Production data'!Q2 -> 1859 | BP3: =IF((BO3=0),0,BN3/BO3) -> 0.50511027 | BQ3: =BP3*9.04 -> 4.5661969 | BR3: 903 | BS3: ='Production data'!R2 -> 1800 | BT3: =IF((BS3=0),0,BR3/BS3) -> 0.50166667 | BU3: =BT3*9.04 -> 4.5350667 | BV3: 773 | BW3: ='Production data'!S2 -> 1362 | BX3: =IF((BW3=0),0,BV3/BW3) -> 0.56754772 | BY3: =BX3*9.04 -> 5.1306314 | BZ3: 872 | CA3: ='Production data'!T2 -> 1683 | CB3: =IF((CA3=0),0,BZ3/CA3) -> 0.5181224 | CC3: =CB3*9.04 -> 4.6838265 | CD3: 972 | CE3: ='Production data'!U2 -> 1535 | CF3: =IF((CE3=0),0,CD3/CE3) -> 0.63322476 | CG3: =CF3*9.04 -> 5.7243518 | CH3: 488 | CI3: ='Production data'!V2 -> 799 | CJ3: =IF((CI3=0),0,CH3/CI3) -> 0.61076345 | CK3: =CJ3*9.04 -> 5.5213016 | CL3: 832 | CM3: ='Production data'!W2 -> 1820 | CN3: =IF((CM3=0),0,CL3/CM3) -> 0.45714286 | CO3: =CN3*9.04 -> 4.1325714 | CP3: 921 | CQ3: ='Production data'!X2 -> 1481 | CR3: =IF((CQ3=0),0,CP3/CQ3) -> 0.62187711 | CS3: =CR3*9.04 -> 5.6217691 | CT3: 898 | CU3: ='Production data'!Y2 -> 1654 | CV3: =IF((CU3=0),0,CT3/CU3) -> 0.54292624 | CW3: =CV3*9.04 -> 4.9080532 | CX3: 962 | CY3: ='Production data'!Z2 -> 2012 | CZ3: =IF((CY3=0),0,CX3/CY3) -> 0.47813121 | DA3: =CZ3*9.04 -> 4.3223062 | DB3: 928 | DC3: ='Production data'!AA2 -> 1754 | DD3: =IF((DC3=0),0,DB3/DC3) -> 0.5290764 | DE3: =DD3*9.04 -> 4.7828506 | DF3: 965 | DG3: ='Production data'!AB2 -> 1893 | DH3: =IF((DG3=0),0,DF3/DG3) -> 0.50977285 | DI3: =DH3*9.04 -> 4.6083465 | DJ3: 710 | DK3: ='Production data'!AC2 -> 1442 | DL3: =IF((DK3=0),0,DJ3/DK3) -> 0.49237171 | DM3: =DL3*9.04 -> 4.4510402 | DN3: 968 | DO3: ='Production data'!AD2 -> 1553 | DP3: =IF((DO3=0),0,DN3/DO3) -> 0.62330972 | DQ3: =DP3*9.04 -> 5.6347199 | DR3: 280 | DS3: ='Production data'!AE2 -> 253 | DT3: =IF((DS3=0),0,DR3/DS3) -> 1.1067194 | DU3: =DT3*9.04 -> 10.004743 | DW3: ='Production data'!AF2 -> 0 | DX3: =IF((DW3=0),0,DV3/DW3) -> 0 | DY3: =DX3*9.04 -> 0 | DZ3: =F3+J3+N3+R3+V3+Z3+AD3+AH3+AL3+AP3+AT3+AX3+BB3+BF3+BJ3+BN3+BR3+BV3+BZ3+CD3+CH3+CL3+CP3+CT3+CX3+DB3+DF3+DJ3+DN3+DR3+DV3 -> 22913 | EA3: =G3+K3+O3+S3+W3+AA3+AI3+AM3+AQ3+AU3+AY3+BC3+BG3+BK3+BO3+BS3+BW3+CA3+CE3+CI3+CM3+CQ3+CU3+CY3+DC3+DG3+DK3+DO3+DS3+DW3 -> 40592 | EB3: =IF((EA3=0),0,DZ3/EA3) -> 0.56447083 | EC3: =EB3*9.04 -> 5.1028163
C4: 14 | D4: LT ROOM COOLING TOWER | F4: 2 | G4: =G3 -> 0 | H4: =IF((G4=0),0,F4/G4) -> 0 | I4: =H4*9.04 -> 0 | J4: 348 | K4: =K3 -> 818 | L4: =IF((K4=0),0,J4/K4) -> 0.42542787 | M4: =L4*9.04 -> 3.845868 | N4: 273 | O4: =O3 -> 1807 | P4: =IF((O4=0),0,N4/O4) -> 0.15107914 | Q4: =P4*9.04 -> 1.3657554 | R4: 309 | S4: =S3 -> 2015 | T4: =IF((S4=0),0,R4/S4) -> 0.15334988 | U4: =T4*9.04 -> 1.3862829 | V4: 319 | W4: =W3 -> 1806 | X4: =IF((W4=0),0,V4/W4) -> 0.17663344 | Y4: =X4*9.04 -> 1.5967663 | Z4: 21 | AA4: =AA3 -> 0 | AB4: =IF((AA4=0),0,Z4/AA4) -> 0 | AC4: =AB4*9.04 -> 0 | AD4: 227 | AE4: =AE3 -> 1310 | AF4: =IF((AE4=0),0,AD4/AE4) -> 0.17328244 | AG4: =AF4*9.04 -> 1.5664733 | AH4: 266 | AI4: =AI3 -> 1189 | AJ4: =IF((AI4=0),0,AH4/AI4) -> 0.22371741 | AK4: =AJ4*9.04 -> 2.0224054 | AL4: 314 | AM4: =AM3 -> 1740 | AN4: =IF((AM4=0),0,AL4/AM4) -> 0.18045977 | AO4: =AN4*9.04 -> 1.6313563 | AP4: 338 | AQ4: =AQ3 -> 929 | AR4: =IF((AQ4=0),0,AP4/AQ4) -> 0.36383208 | AS4: =AR4*9.04 -> 3.289042 | AT4: 277 | AU4: =AU3 -> 1595 | AV4: =IF((AU4=0),0,AT4/AU4) -> 0.17366771 | AW4: =AV4*9.04 -> 1.5699561 | AX4: 265 | AY4: =AY3 -> 1495 | AZ4: =IF((AY4=0),0,AX4/AY4) -> 0.17725753 | BA4: =AZ4*9.04 -> 1.602408 | BB4: 335 | BC4: =BC3 -> 1517 | BD4: =IF((BC4=0),0,BB4/BC4) -> 0.22083059 | BE4: =BD4*9.04 -> 1.9963085 | BF4: 166 | BG4: =BG3 -> 770 | BH4: =IF((BG4=0),0,BF4/BG4) -> 0.21558442 | BI4: =BH4*9.04 -> 1.9488831 | BJ4: 326 | BK4: =BK3 -> 2011 | BL4: =IF((BK4=0),0,BJ4/BK4) -> 0.1621084 | BM4: =BL4*9.04 -> 1.46546 | BN4: 335 | BO4: =BO3 -> 1859 | BP4: =IF((BO4=0),0,BN4/BO4) -> 0.18020441 | BQ4: =BP4*9.04 -> 1.6290479 | BR4: 338 | BS4: =BS3 -> 1800 | BT4: =IF((BS4=0),0,BR4/BS4) -> 0.18777778 | BU4: =BT4*9.04 -> 1.6975111 | BV4: 340 | BW4: =BW3 -> 1362 | BX4: =IF((BW4=0),0,BV4/BW4) -> 0.24963289 | BY4: =BX4*9.04 -> 2.2566814 | BZ4: 337 | CA4: =CA3 -> 1683 | CB4: =IF((CA4=0),0,BZ4/CA4) -> 0.20023767 | CC4: =CB4*9.04 -> 1.8101485 | CD4: 255 | CE4: =CE3 -> 1535 | CF4: =IF((CE4=0),0,CD4/CE4) -> 0.16612378 | CG4: =CF4*9.04 -> 1.501759 | CH4: 100 | CI4: =CI3 -> 799 | CJ4: =IF((CI4=0),0,CH4/CI4) -> 0.12515645 | CK4: =CJ4*9.04 -> 1.1314143 | CL4: 314 | CM4: =CM3 -> 1820 | CN4: =IF((CM4=0),0,CL4/CM4) -> 0.17252747 | CO4: =CN4*9.04 -> 1.5596484 | CP4: 301 | CQ4: =CQ3 -> 1481 | CR4: =IF((CQ4=0),0,CP4/CQ4) -> 0.20324105 | CS4: =CR4*9.04 -> 1.8372991 | CT4: 337 | CU4: =CU3 -> 1654 | CV4: =IF((CU4=0),0,CT4/CU4) -> 0.20374849 | CW4: =CV4*9.04 -> 1.8418863 | CX4: 313 | CY4: =CY3 -> 2012 | CZ4: =IF((CY4=0),0,CX4/CY4) -> 0.1555666 | DA4: =CZ4*9.04 -> 1.4063221 | DB4: 270 | DC4: =DC3 -> 1754 | DD4: =IF((DC4=0),0,DB4/DC4) -> 0.15393387 | DE4: =DD4*9.04 -> 1.3915621 | DF4: 301 | DG4: =DG3 -> 1893 | DH4: =IF((DG4=0),0,DF4/DG4) -> 0.15900687 | DI4: =DH4*9.04 -> 1.4374221 | DJ4: 230 | DK4: =DK3 -> 1442 | DL4: =IF((DK4=0),0,DJ4/DK4) -> 0.15950069 | DM4: =DL4*9.04 -> 1.4418863 | DN4: 352 | DO4: =DO3 -> 1553 | DP4: =IF((DO4=0),0,DN4/DO4) -> 0.22665808 | DQ4: =DP4*9.04 -> 2.0489891 | DR4: 248 | DS4: =DS3 -> 253 | DT4: =IF((DS4=0),0,DR4/DS4) -> 0.98023715 | DU4: =DT4*9.04 -> 8.8613439 | DW4: =DW3 -> 0 | DX4: =IF((DW4=0),0,DV4/DW4) -> 0 | DY4: =DX4*9.04 -> 0 | DZ4: =F4+J4+N4+R4+V4+Z4+AD4+AH4+AL4+AP4+AT4+AX4+BB4+BF4+BJ4+BN4+BR4+BV4+BZ4+CD4+CH4+CL4+CP4+CT4+CX4+DB4+DF4+DJ4+DN4+DR4+DV4 -> 8157 | EA4: =G4+K4+O4+S4+W4+AA4+AI4+AM4+AQ4+AU4+AY4+BC4+BG4+BK4+BO4+BS4+BW4+CA4+CE4+CI4+CM4+CQ4+CU4+CY4+DC4+DG4+DK4+DO4+DS4+DW4 -> 40592 | EB4: =IF((EA4=0),0,DZ4/EA4) -> 0.20095093 | EC4: =EB4*9.04 -> 1.8165964
C5: 48 | D5: TF MPI | F5: 0 | G5: =G3 -> 0 | H5: =IF((G5=0),0,F5/G5) -> 0 | I5: =H5*9.04 -> 0 | J5: 11 | K5: =K3 -> 818 | L5: =IF((K5=0),0,J5/K5) -> 0.013447433 | M5: =L5*9.04 -> 0.12156479 | N5: 12 | O5: =O3 -> 1807 | P5: =IF((O5=0),0,N5/O5) -> 0.0066408412 | Q5: =P5*9.04 -> 0.060033204 | R5: 14 | S5: =S3 -> 2015 | T5: =IF((S5=0),0,R5/S5) -> 0.0069478908 | U5: =T5*9.04 -> 0.062808933 | V5: 12 | W5: =W3 -> 1806 | X5: =IF((W5=0),0,V5/W5) -> 0.0066445183 | Y5: =X5*9.04 -> 0.060066445 | Z5: 0 | AA5: =AA3 -> 0 | AB5: =IF((AA5=0),0,Z5/AA5) -> 0 | AC5: =AB5*9.04 -> 0 | AD5: 10 | AE5: =AE3 -> 1310 | AF5: =IF((AE5=0),0,AD5/AE5) -> 0.0076335878 | AG5: =AF5*9.04 -> 0.069007634 | AH5: 12 | AI5: =AI3 -> 1189 | AJ5: =IF((AI5=0),0,AH5/AI5) -> 0.010092515 | AK5: =AJ5*9.04 -> 0.091236333 | AL5: 13 | AM5: =AM3 -> 1740 | AN5: =IF((AM5=0),0,AL5/AM5) -> 0.0074712644 | AO5: =AN5*9.04 -> 0.06754023 | AP5: 11 | AQ5: =AQ3 -> 929 | AR5: =IF((AQ5=0),0,AP5/AQ5) -> 0.011840689 | AS5: =AR5*9.04 -> 0.10703983 | AT5: 14 | AU5: =AU3 -> 1595 | AV5: =IF((AU5=0),0,AT5/AU5) -> 0.0087774295 | AW5: =AV5*9.04 -> 0.079347962 | AX5: 16 | AY5: =AY3 -> 1495 | AZ5: =IF((AY5=0),0,AX5/AY5) -> 0.010702341 | BA5: =AZ5*9.04 -> 0.096749164 | BB5: 11 | BC5: =BC3 -> 1517 | BD5: =IF((BC5=0),0,BB5/BC5) -> 0.0072511536 | BE5: =BD5*9.04 -> 0.065550428 | BF5: 9 | BG5: =BG3 -> 770 | BH5: =IF((BG5=0),0,BF5/BG5) -> 0.011688312 | BI5: =BH5*9.04 -> 0.10566234 | BJ5: 13 | BK5: =BK3 -> 2011 | BL5: =IF((BK5=0),0,BJ5/BK5) -> 0.0064644455 | BM5: =BL5*9.04 -> 0.058438588 | BN5: 14 | BO5: =BO3 -> 1859 | BP5: =IF((BO5=0),0,BN5/BO5) -> 0.0075309306 | BQ5: =BP5*9.04 -> 0.068079613 | BR5: 13 | BS5: =BS3 -> 1800 | BT5: =IF((BS5=0),0,BR5/BS5) -> 0.0072222222 | BU5: =BT5*9.04 -> 0.065288889 | BV5: 13 | BW5: =BW3 -> 1362 | BX5: =IF((BW5=0),0,BV5/BW5) -> 0.0095447871 | BY5: =BX5*9.04 -> 0.086284875 | BZ5: 13 | CA5: =CA3 -> 1683 | CB5: =IF((CA5=0),0,BZ5/CA5) -> 0.0077243018 | CC5: =CB5*9.04 -> 0.069827689 | CD5: 12 | CE5: =CE3 -> 1535 | CF5: =IF((CE5=0),0,CD5/CE5) -> 0.0078175896 | CG5: =CF5*9.04 -> 0.07067101 | CH5: 6 | CI5: =CI3 -> 799 | CJ5: =IF((CI5=0),0,CH5/CI5) -> 0.0075093867 | CK5: =CJ5*9.04 -> 0.067884856 | CL5: 12 | CM5: =CM3 -> 1820 | CN5: =IF((CM5=0),0,CL5/CM5) -> 0.0065934066 | CO5: =CN5*9.04 -> 0.059604396 | CP5: 10 | CQ5: =CQ3 -> 1481 | CR5: =IF((CQ5=0),0,CP5/CQ5) -> 0.0067521945 | CS5: =CR5*9.04 -> 0.061039838 | CT5: 12 | CU5: =CU3 -> 1654 | CV5: =IF((CU5=0),0,CT5/CU5) -> 0.0072551391 | CW5: =CV5*9.04 -> 0.065586457 | CX5: 13 | CY5: =CY3 -> 2012 | CZ5: =IF((CY5=0),0,CX5/CY5) -> 0.0064612326 | DA5: =CZ5*9.04 -> 0.058409543 | DB5: 13 | DC5: =DC3 -> 1754 | DD5: =IF((DC5=0),0,DB5/DC5) -> 0.0074116306 | DE5: =DD5*9.04 -> 0.06700114 | DF5: 13 | DG5: =DG3 -> 1893 | DH5: =IF((DG5=0),0,DF5/DG5) -> 0.0068674062 | DI5: =DH5*9.04 -> 0.062081352 | DJ5: 18 | DK5: =DK3 -> 1442 | DL5: =IF((DK5=0),0,DJ5/DK5) -> 0.012482663 | DM5: =DL5*9.04 -> 0.11284327 | DN5: 8 | DO5: =DO3 -> 1553 | DP5: =IF((DO5=0),0,DN5/DO5) -> 0.00515132 | DQ5: =DP5*9.04 -> 0.046567933 | DR5: 11 | DS5: =DS3 -> 253 | DT5: =IF((DS5=0),0,DR5/DS5) -> 0.043478261 | DU5: =DT5*9.04 -> 0.39304348 | DW5: =DW3 -> 0 | DX5: =IF((DW5=0),0,DV5/DW5) -> 0 | DY5: =DX5*9.04 -> 0 | DZ5: =F5+J5+N5+R5+V5+Z5+AD5+AH5+AL5+AP5+AT5+AX5+BB5+BF5+BJ5+BN5+BR5+BV5+BZ5+CD5+CH5+CL5+CP5+CT5+CX5+DB5+DF5+DJ5+DN5+DR5+DV5 -> 339 | EA5: =G5+K5+O5+S5+W5+AA5+AI5+AM5+AQ5+AU5+AY5+BC5+BG5+BK5+BO5+BS5+BW5+CA5+CE5+CI5+CM5+CQ5+CU5+CY5+DC5+DG5+DK5+DO5+DS5+DW5 -> 40592 | EB5: =IF((EA5=0),0,DZ5/EA5) -> 0.0083513993 | EC5: =EB5*9.04 -> 0.07549665
C6: 38 | D6: WHEEL FLANGE OD GRINDING | F6: 1 | G6: ='Production data'!B3 -> 0 | H6: =IF((G6=0),0,F6/G6) -> 0 | I6: =H6*9.04 -> 0 | J6: 34 | K6: ='Production data'!C3 -> 331 | L6: =IF((K6=0),0,J6/K6) -> 0.10271903 | M6: =L6*9.04 -> 0.92858006 | N6: 36 | O6: ='Production data'!D3 -> 1041 | P6: =IF((O6=0),0,N6/O6) -> 0.034582133 | Q6: =P6*9.04 -> 0.31262248 | R6: 40 | S6: ='Production data'!E3 -> 955 | T6: =IF((S6=0),0,R6/S6) -> 0.041884817 | U6: =T6*9.04 -> 0.37863874 | V6: 29 | W6: ='Production data'!F3 -> 396 | X6: =IF((W6=0),0,V6/W6) -> 0.073232323 | Y6: =X6*9.04 -> 0.6620202 | Z6: 1 | AA6: ='Production data'!G3 -> 0 | AB6: =IF((AA6=0),0,Z6/AA6) -> 0 | AC6: =AB6*9.04 -> 0 | AD6: 38 | AE6: ='Production data'!H3 -> 771 | AF6: =IF((AE6=0),0,AD6/AE6) -> 0.049286641 | AG6: =AF6*9.04 -> 0.44555123 | AH6: 21 | AI6: ='Production data'!I3 -> 537 | AJ6: =IF((AI6=0),0,AH6/AI6) -> 0.039106145 | AK6: =AJ6*9.04 -> 0.35351955 | AL6: 52 | AM6: ='Production data'!J3 -> 1075 | AN6: =IF((AM6=0),0,AL6/AM6) -> 0.048372093 | AO6: =AN6*9.04 -> 0.43728372 | AP6: 41 | AQ6: ='Production data'!K3 -> 466 | AR6: =IF((AQ6=0),0,AP6/AQ6) -> 0.087982833 | AS6: =AR6*9.04 -> 0.79536481 | AT6: 46 | AU6: ='Production data'!L3 -> 881 | AV6: =IF((AU6=0),0,AT6/AU6) -> 0.052213394 | AW6: =AV6*9.04 -> 0.47200908 | AX6: 44 | AY6: ='Production data'!M3 -> 766 | AZ6: =IF((AY6=0),0,AX6/AY6) -> 0.057441253 | BA6: =AZ6*9.04 -> 0.51926893 | BB6: 41 | BC6: ='Production data'!N3 -> 726 | BD6: =IF((BC6=0),0,BB6/BC6) -> 0.056473829 | BE6: =BD6*9.04 -> 0.51052342 | BF6: 17 | BG6: ='Production data'!O3 -> 300 | BH6: =IF((BG6=0),0,BF6/BG6) -> 0.056666667 | BI6: =BH6*9.04 -> 0.51226667 | BJ6: 43 | BK6: ='Production data'!P3 -> 876 | BL6: =IF((BK6=0),0,BJ6/BK6) -> 0.049086758 | BM6: =BL6*9.04 -> 0.44374429 | BN6: 41 | BO6: ='Production data'!Q3 -> 978 | BP6: =IF((BO6=0),0,BN6/BO6) -> 0.04192229 | BQ6: =BP6*9.04 -> 0.37897751 | BR6: 38 | BS6: ='Production data'!R3 -> 1037 | BT6: =IF((BS6=0),0,BR6/BS6) -> 0.036644166 | BU6: =BT6*9.04 -> 0.33126326 | BV6: 39 | BW6: ='Production data'!S3 -> 816 | BX6: =IF((BW6=0),0,BV6/BW6) -> 0.047794118 | BY6: =BX6*9.04 -> 0.43205882 | BZ6: 13 | CA6: ='Production data'!T3 -> 0 | CB6: =IF((CA6=0),0,BZ6/CA6) -> 0 | CC6: =CB6*9.04 -> 0 | CD6: 36 | CE6: ='Production data'!U3 -> 881 | CF6: =IF((CE6=0),0,CD6/CE6) -> 0.040862656 | CG6: =CF6*9.04 -> 0.36939841 | CH6: 19 | CI6: ='Production data'!V3 -> 369 | CJ6: =IF((CI6=0),0,CH6/CI6) -> 0.051490515 | CK6: =CJ6*9.04 -> 0.46547425 | CL6: 29 | CM6: ='Production data'!W3 -> 495 | CN6: =IF((CM6=0),0,CL6/CM6) -> 0.058585859 | CO6: =CN6*9.04 -> 0.52961616 | CP6: 19 | CQ6: ='Production data'!X3 -> 704 | CR6: =IF((CQ6=0),0,CP6/CQ6) -> 0.026988636 | CS6: =CR6*9.04 -> 0.24397727 | CT6: 43 | CU6: ='Production data'!Y3 -> 955 | CV6: =IF((CU6=0),0,CT6/CU6) -> 0.045026178 | CW6: =CV6*9.04 -> 0.40703665 | CX6: 25 | CY6: ='Production data'!Z3 -> 248 | CZ6: =IF((CY6=0),0,CX6/CY6) -> 0.10080645 | DA6: =CZ6*9.04 -> 0.91129032 | DB6: 32 | DC6: ='Production data'!AA3 -> 510 | DD6: =IF((DC6=0),0,DB6/DC6) -> 0.062745098 | DE6: =DD6*9.04 -> 0.56721569 | DF6: 40 | DG6: ='Production data'!AB3 -> 706 | DH6: =IF((DG6=0),0,DF6/DG6) -> 0.056657224 | DI6: =DH6*9.04 -> 0.5121813 | DJ6: 40 | DK6: ='Production data'!AC3 -> 652 | DL6: =IF((DK6=0),0,DJ6/DK6) -> 0.061349693 | DM6: =DL6*9.04 -> 0.55460123 | DN6: 41 | DO6: ='Production data'!AD3 -> 932 | DP6: =IF((DO6=0),0,DN6/DO6) -> 0.043991416 | DQ6: =DP6*9.04 -> 0.3976824 | DR6: 21 | DS6: ='Production data'!AE3 -> 154 | DT6: =IF((DS6=0),0,DR6/DS6) -> 0.13636364 | DU6: =DT6*9.04 -> 1.2327273 | DW6: ='Production data'!AF3 -> 0 | DX6: =IF((DW6=0),0,DV6/DW6) -> 0 | DY6: =DX6*9.04 -> 0 | DZ6: =F6+J6+N6+R6+V6+Z6+AD6+AH6+AL6+AP6+AT6+AX6+BB6+BF6+BJ6+BN6+BR6+BV6+BZ6+CD6+CH6+CL6+CP6+CT6+CX6+DB6+DF6+DJ6+DN6+DR6+DV6 -> 960 | EA6: =G6+K6+O6+S6+W6+AA6+AI6+AM6+AQ6+AU6+AY6+BC6+BG6+BK6+BO6+BS6+BW6+CA6+CE6+CI6+CM6+CQ6+CU6+CY6+DC6+DG6+DK6+DO6+DS6+DW6 -> 17787 | EB6: =IF((EA6=0),0,DZ6/EA6) -> 0.053972002 | EC6: =EB6*9.04 -> 0.4879069
C7: 50 | D7: TF OD GRINDING | F7: 0 | G7: ='Production data'!B4 -> 0 | H7: =IF((G7=0),0,F7/G7) -> 0 | I7: =H7*9.04 -> 0 | J7: 0 | K7: ='Production data'!C4 -> 0 | L7: =IF((K7=0),0,J7/K7) -> 0 | M7: =L7*9.04 -> 0 | N7: 22 | O7: ='Production data'!D4 -> 0 | P7: =IF((O7=0),0,N7/O7) -> 0 | Q7: =P7*9.04 -> 0 | R7: 22 | S7: ='Production data'!E4 -> 0 | T7: =IF((S7=0),0,R7/S7) -> 0 | U7: =T7*9.04 -> 0 | V7: 17 | W7: ='Production data'!F4 -> 0 | X7: =IF((W7=0),0,V7/W7) -> 0 | Y7: =X7*9.04 -> 0 | Z7: 1 | AA7: ='Production data'!G4 -> 0 | AB7: =IF((AA7=0),0,Z7/AA7) -> 0 | AC7: =AB7*9.04 -> 0 | AD7: 20 | AE7: ='Production data'!H4 -> 0 | AF7: =IF((AE7=0),0,AD7/AE7) -> 0 | AG7: =AF7*9.04 -> 0 | AH7: 20 | AI7: ='Production data'!I4 -> 0 | AJ7: =IF((AI7=0),0,AH7/AI7) -> 0 | AK7: =AJ7*9.04 -> 0 | AL7: 23 | AM7: ='Production data'!J4 -> 0 | AN7: =IF((AM7=0),0,AL7/AM7) -> 0 | AO7: =AN7*9.04 -> 0 | AP7: 18 | AQ7: ='Production data'!K4 -> 0 | AR7: =IF((AQ7=0),0,AP7/AQ7) -> 0 | AS7: =AR7*9.04 -> 0 | AT7: 21 | AU7: ='Production data'!L4 -> 0 | AV7: =IF((AU7=0),0,AT7/AU7) -> 0 | AW7: =AV7*9.04 -> 0 | AX7: 20 | AY7: ='Production data'!M4 -> 0 | AZ7: =IF((AY7=0),0,AX7/AY7) -> 0 | BA7: =AZ7*9.04 -> 0 | BB7: 12 | BC7: ='Production data'!N4 -> 0 | BD7: =IF((BC7=0),0,BB7/BC7) -> 0 | BE7: =BD7*9.04 -> 0 | BF7: 11 | BG7: ='Production data'!O4 -> 0 | BH7: =IF((BG7=0),0,BF7/BG7) -> 0 | BI7: =BH7*9.04 -> 0 | BJ7: 20 | BK7: ='Production data'!P4 -> 0 | BL7: =IF((BK7=0),0,BJ7/BK7) -> 0 | BM7: =BL7*9.04 -> 0 | BN7: 20 | BO7: ='Production data'!Q4 -> 0 | BP7: =IF((BO7=0),0,BN7/BO7) -> 0 | BQ7: =BP7*9.04 -> 0 | BR7: 20 | BS7: ='Production data'!R4 -> 0 | BT7: =IF((BS7=0),0,BR7/BS7) -> 0 | BU7: =BT7*9.04 -> 0 | BV7: 17 | BW7: ='Production data'!S4 -> 0 | BX7: =IF((BW7=0),0,BV7/BW7) -> 0 | BY7: =BX7*9.04 -> 0 | BZ7: 6 | CA7: ='Production data'!T4 -> 0 | CB7: =IF((CA7=0),0,BZ7/CA7) -> 0 | CC7: =CB7*9.04 -> 0 | CD7: 17 | CE7: ='Production data'!U4 -> 0 | CF7: =IF((CE7=0),0,CD7/CE7) -> 0 | CG7: =CF7*9.04 -> 0 | CH7: 9 | CI7: ='Production data'!V4 -> 0 | CJ7: =IF((CI7=0),0,CH7/CI7) -> 0 | CK7: =CJ7*9.04 -> 0 | CL7: 13 | CM7: ='Production data'!W4 -> 0 | CN7: =IF((CM7=0),0,CL7/CM7) -> 0 | CO7: =CN7*9.04 -> 0 | CP7: 14 | CQ7: ='Production data'!X4 -> 0 | CR7: =IF((CQ7=0),0,CP7/CQ7) -> 0 | CS7: =CR7*9.04 -> 0 | CT7: 22 | CU7: ='Production data'!Y4 -> 0 | CV7: =IF((CU7=0),0,CT7/CU7) -> 0 | CW7: =CV7*9.04 -> 0 | CX7: 16 | CY7: ='Production data'!Z4 -> 0 | CZ7: =IF((CY7=0),0,CX7/CY7) -> 0 | DA7: =CZ7*9.04 -> 0 | DB7: 14 | DC7: ='Production data'!AA4 -> 0 | DD7: =IF((DC7=0),0,DB7/DC7) -> 0 | DE7: =DD7*9.04 -> 0 | DF7: 66 | DG7: ='Production data'!AB4 -> 0 | DH7: =IF((DG7=0),0,DF7/DG7) -> 0 | DI7: =DH7*9.04 -> 0 | DJ7: 4 | DK7: ='Production data'!AC4 -> 0 | DL7: =IF((DK7=0),0,DJ7/DK7) -> 0 | DM7: =DL7*9.04 -> 0 | DN7: 19 | DO7: ='Production data'!AD4 -> 0 | DP7: =IF((DO7=0),0,DN7/DO7) -> 0 | DQ7: =DP7*9.04 -> 0 | DR7: 9 | DS7: ='Production data'!AE4 -> 0 | DT7: =IF((DS7=0),0,DR7/DS7) -> 0 | DU7: =DT7*9.04 -> 0 | DW7: ='Production data'!AF4 -> 0 | DX7: =IF((DW7=0),0,DV7/DW7) -> 0 | DY7: =DX7*9.04 -> 0 | DZ7: =F7+J7+N7+R7+V7+Z7+AD7+AH7+AL7+AP7+AT7+AX7+BB7+BF7+BJ7+BN7+BR7+BV7+BZ7+CD7+CH7+CL7+CP7+CT7+CX7+DB7+DF7+DJ7+DN7+DR7+DV7 -> 493 | EA7: =G7+K7+O7+S7+W7+AA7+AI7+AM7+AQ7+AU7+AY7+BC7+BG7+BK7+BO7+BS7+BW7+CA7+CE7+CI7+CM7+CQ7+CU7+CY7+DC7+DG7+DK7+DO7+DS7+DW7 -> 0 | EB7: =IF((EA7=0),0,DZ7/EA7) -> 0 | EC7: =EB7*9.04 -> 0
C8: 42 | D8: WHEEL FLANGE ROBO 894 | F8: 0 | G8: =G7+G6 -> 0 | H8: =IF((G8=0),0,F8/G8) -> 0 | I8: =H8*9.04 -> 0 | J8: 11 | K8: =K7+K6 -> 331 | L8: =IF((K8=0),0,J8/K8) -> 0.033232628 | M8: =L8*9.04 -> 0.30042296 | N8: 12 | O8: =O7+O6 -> 1041 | P8: =IF((O8=0),0,N8/O8) -> 0.011527378 | Q8: =P8*9.04 -> 0.10420749 | R8: 14 | S8: =S7+S6 -> 955 | T8: =IF((S8=0),0,R8/S8) -> 0.014659686 | U8: =T8*9.04 -> 0.13252356 | V8: 11 | W8: =W7+W6 -> 396 | X8: =IF((W8=0),0,V8/W8) -> 0.027777778 | Y8: =X8*9.04 -> 0.25111111 | Z8: 1 | AA8: =AA7+AA6 -> 0 | AB8: =IF((AA8=0),0,Z8/AA8) -> 0 | AC8: =AB8*9.04 -> 0 | AD8: 12 | AE8: =AE7+AE6 -> 771 | AF8: =IF((AE8=0),0,AD8/AE8) -> 0.015564202 | AG8: =AF8*9.04 -> 0.14070039 | AH8: 16 | AI8: =AI7+AI6 -> 537 | AJ8: =IF((AI8=0),0,AH8/AI8) -> 0.029795158 | AK8: =AJ8*9.04 -> 0.26934823 | AL8: 19 | AM8: =AM7+AM6 -> 1075 | AN8: =IF((AM8=0),0,AL8/AM8) -> 0.017674419 | AO8: =AN8*9.04 -> 0.15977674 | AP8: 16 | AQ8: =AQ7+AQ6 -> 466 | AR8: =IF((AQ8=0),0,AP8/AQ8) -> 0.034334764 | AS8: =AR8*9.04 -> 0.31038627 | AT8: 18 | AU8: =AU7+AU6 -> 881 | AV8: =IF((AU8=0),0,AT8/AU8) -> 0.020431328 | AW8: =AV8*9.04 -> 0.18469921 | AX8: 18 | AY8: =AY7+AY6 -> 766 | AZ8: =IF((AY8=0),0,AX8/AY8) -> 0.023498695 | BA8: =AZ8*9.04 -> 0.2124282 | BB8: 18 | BC8: =BC7+BC6 -> 726 | BD8: =IF((BC8=0),0,BB8/BC8) -> 0.024793388 | BE8: =BD8*9.04 -> 0.22413223 | BF8: 8 | BG8: =BG7+BG6 -> 300 | BH8: =IF((BG8=0),0,BF8/BG8) -> 0.026666667 | BI8: =BH8*9.04 -> 0.24106667 | BJ8: 18 | BK8: =BK7+BK6 -> 876 | BL8: =IF((BK8=0),0,BJ8/BK8) -> 0.020547945 | BM8: =BL8*9.04 -> 0.18575342 | BN8: 18 | BO8: =BO7+BO6 -> 978 | BP8: =IF((BO8=0),0,BN8/BO8) -> 0.018404908 | BQ8: =BP8*9.04 -> 0.16638037 | BR8: 20 | BS8: =BS7+BS6 -> 1037 | BT8: =IF((BS8=0),0,BR8/BS8) -> 0.019286403 | BU8: =BT8*9.04 -> 0.17434908 | BV8: 18 | BW8: =BW7+BW6 -> 816 | BX8: =IF((BW8=0),0,BV8/BW8) -> 0.022058824 | BY8: =BX8*9.04 -> 0.19941176 | BZ8: 8 | CA8: =CA7+CA6 -> 0 | CB8: =IF((CA8=0),0,BZ8/CA8) -> 0 | CC8: =CB8*9.04 -> 0 | CD8: 16 | CE8: =CE7+CE6 -> 881 | CF8: =IF((CE8=0),0,CD8/CE8) -> 0.01816118 | CG8: =CF8*9.04 -> 0.16417707 | CH8: 8 | CI8: =CI7+CI6 -> 369 | CJ8: =IF((CI8=0),0,CH8/CI8) -> 0.021680217 | CK8: =CJ8*9.04 -> 0.19598916 | CL8: 8 | CM8: =CM7+CM6 -> 495 | CN8: =IF((CM8=0),0,CL8/CM8) -> 0.016161616 | CO8: =CN8*9.04 -> 0.14610101 | CP8: 9 | CQ8: =CQ7+CQ6 -> 704 | CR8: =IF((CQ8=0),0,CP8/CQ8) -> 0.012784091 | CS8: =CR8*9.04 -> 0.11556818 | CT8: 14 | CU8: =CU7+CU6 -> 955 | CV8: =IF((CU8=0),0,CT8/CU8) -> 0.014659686 | CW8: =CV8*9.04 -> 0.13252356 | CX8: 11 | CY8: =CY7+CY6 -> 248 | CZ8: =IF((CY8=0),0,CX8/CY8) -> 0.044354839 | DA8: =CZ8*9.04 -> 0.40096774 | DB8: 11 | DC8: =DC7+DC6 -> 510 | DD8: =IF((DC8=0),0,DB8/DC8) -> 0.021568627 | DE8: =DD8*9.04 -> 0.19498039 | DF8: 14 | DG8: =DG7+DG6 -> 706 | DH8: =IF((DG8=0),0,DF8/DG8) -> 0.019830028 | DI8: =DH8*9.04 -> 0.17926346 | DJ8: 10 | DK8: =DK7+DK6 -> 652 | DL8: =IF((DK8=0),0,DJ8/DK8) -> 0.015337423 | DM8: =DL8*9.04 -> 0.13865031 | DN8: 16 | DO8: =DO7+DO6 -> 932 | DP8: =IF((DO8=0),0,DN8/DO8) -> 0.017167382 | DQ8: =DP8*9.04 -> 0.15519313 | DR8: 8 | DS8: =DS7+DS6 -> 154 | DT8: =IF((DS8=0),0,DR8/DS8) -> 0.051948052 | DU8: =DT8*9.04 -> 0.46961039 | DW8: =DW7+DW6 -> 0 | DX8: =IF((DW8=0),0,DV8/DW8) -> 0 | DY8: =DX8*9.04 -> 0 | DZ8: =F8+J8+N8+R8+V8+Z8+AD8+AH8+AL8+AP8+AT8+AX8+BB8+BF8+BJ8+BN8+BR8+BV8+BZ8+CD8+CH8+CL8+CP8+CT8+CX8+DB8+DF8+DJ8+DN8+DR8+DV8 -> 381 | EA8: =G8+K8+O8+S8+W8+AA8+AI8+AM8+AQ8+AU8+AY8+BC8+BG8+BK8+BO8+BS8+BW8+CA8+CE8+CI8+CM8+CQ8+CU8+CY8+DC8+DG8+DK8+DO8+DS8+DW8 -> 17787 | EB8: =IF((EA8=0),0,DZ8/EA8) -> 0.021420138 | EC8: =EB8*9.04 -> 0.19363805
D9: Total OD Grinding | F9: =SUM(F6:F8) -> 1 | G9: =SUM(G6:G8) -> 0 | H9: =SUM(H6:H8) -> 0 | I9: =SUM(I6:I8) -> 0 | J9: =SUM(J6:J8) -> 45 | K9: =SUM(K6:K8) -> 662 | L9: =SUM(L6:L8) -> 0.13595166 | M9: =SUM(M6:M8) -> 1.229003 | ... EC9: =SUM(EC6:EC8) -> 0.68154495
C11: 21 | D11: SHAFT UNO CNC 1 | E11: Shaft Line | F11: 1 | G11: ='Production data'!B5 -> 0 | H11: =IF((G11=0),0,F11/G11) -> 0 | I11: =H11*9.04 -> 0 | J11: 63 | K11: ='Production data'!C5 -> 623 | L11: =IF((K11=0),0,J11/K11) -> 0.1011236 | M11: =L11*9.04 -> 0.9141573 | N11: 35 | O11: ='Production data'!D5 -> 370 | P11: =IF((O11=0),0,N11/O11) -> 0.094594595 | Q11: =P11*9.04 -> 0.85513514 | R11: 61 | S11: ='Production data'!E5 -> 580 | T11: =IF((S11=0),0,R11/S11) -> 0.10517241 | U11: =T11*9.04 -> 0.95075862 | V11: 35 | W11: ='Production data'!F5 -> 300 | X11: =IF((W11=0),0,V11/W11) -> 0.11666667 | Y11: =X11*9.04 -> 1.0546667 | Z11: 2 | AA11: ='Production data'!G5 -> 0 | AB11: =IF((AA11=0),0,Z11/AA11) -> 0 | AC11: =AB11*9.04 -> 0 | AD11: 47 | AE11: ='Production data'!H5 -> 448 | AF11: =IF((AE11=0),0,AD11/AE11) -> 0.10491071 | AG11: =AF11*9.04 -> 0.94839286 | AH11: 40 | AI11: ='Production data'!I5 -> 400 | AJ11: =IF((AI11=0),0,AH11/AI11) -> 0.1 | AK11: =AJ11*9.04 -> 0.904 | AL11: 45 | AM11: ='Production data'!J5 -> 347 | AN11: =IF((AM11=0),0,AL11/AM11) -> 0.129683 | AO11: =AN11*9.04 -> 1.1723343 | AP11: 61 | AQ11: ='Production data'!K5 -> 473 | AR11: =IF((AQ11=0),0,AP11/AQ11) -> 0.12896406 | AS11: =AR11*9.04 -> 1.1658351 | AT11: 56 | AU11: ='Production data'!L5 -> 432 | AV11: =IF((AU11=0),0,AT11/AU11) -> 0.12962963 | AW11: =AV11*9.04 -> 1.1718519 | AX11: 61 | AY11: ='Production data'!M5 -> 550 | AZ11: =IF((AY11=0),0,AX11/AY11) -> 0.11090909 | BA11: =AZ11*9.04 -> 1.0026182 | BB11: 69 | BC11: ='Production data'!N5 -> 670 | BD11: =IF((BC11=0),0,BB11/BC11) -> 0.10298507 | BE11: =BD11*9.04 -> 0.93098507 | BF11: 31 | BG11: ='Production data'!O5 -> 260 | BH11: =IF((BG11=0),0,BF11/BG11) -> 0.11923077 | BI11: =BH11*9.04 -> 1.0778462 | BJ11: 71 | BK11: ='Production data'!P5 -> 711 | BL11: =IF((BK11=0),0,BJ11/BK11) -> 0.099859353 | BM11: =BL11*9.04 -> 0.90272855 | BN11: 70 | BO11: ='Production data'!Q5 -> 749 | BP11: =IF((BO11=0),0,BN11/BO11) -> 0.093457944 | BQ11: =BP11*9.04 -> 0.84485981 | BR11: 27 | BS11: ='Production data'!R5 -> 192 | BT11: =IF((BS11=0),0,BR11/BS11) -> 0.140625 | BU11: =BT11*9.04 -> 1.27125 | BV11: 58 | BW11: ='Production data'!S5 -> 560 | BX11: =IF((BW11=0),0,BV11/BW11) -> 0.10357143 | BY11: =BX11*9.04 -> 0.93628571 | BZ11: 77 | CA11: ='Production data'!T5 -> 804 | CB11: =IF((CA11=0),0,BZ11/CA11) -> 0.095771144 | CC11: =CB11*9.04 -> 0.86577114 | CD11: 75 | CE11: ='Production data'!U5 -> 821 | CF11: =IF((CE11=0),0,CD11/CE11) -> 0.09135201 | CG11: =CF11*9.04 -> 0.82582217 | CH11: 4 | CI11: ='Production data'!V5 -> 0 | CJ11: =IF((CI11=0),0,CH11/CI11) -> 0 | CK11: =CJ11*9.04 -> 0 | CL11: 60 | CM11: ='Production data'!W5 -> 635 | CN11: =IF((CM11=0),0,CL11/CM11) -> 0.094488189 | CO11: =CN11*9.04 -> 0.85417323 | CP11: 33 | CQ11: ='Production data'!X5 -> 271 | CR11: =IF((CQ11=0),0,CP11/CQ11) -> 0.12177122 | CS11: =CR11*9.04 -> 1.1008118 | CT11: 23 | CU11: ='Production data'!Y5 -> 150 | CV11: =IF((CU11=0),0,CT11/CU11) -> 0.15333333 | CW11: =CV11*9.04 -> 1.3861333 | CX11: 20 | CY11: ='Production data'!Z5 -> 130 | CZ11: =IF((CY11=0),0,CX11/CY11) -> 0.15384615 | DA11: =CZ11*9.04 -> 1.3907692 | DB11: 55 | DC11: ='Production data'!AA5 -> 442 | DD11: =IF((DC11=0),0,DB11/DC11) -> 0.12443439 | DE11: =DD11*9.04 -> 1.1248869 | DF11: 57 | DG11: ='Production data'!AB5 -> 550 | DH11: =IF((DG11=0),0,DF11/DG11) -> 0.10363636 | DI11: =DH11*9.04 -> 0.93687273 | DJ11: 25 | DK11: ='Production data'!AC5 -> 130 | DL11: =IF((DK11=0),0,DJ11/DK11) -> 0.19230769 | DM11: =DL11*9.04 -> 1.7384615 | DN11: 69 | DO11: ='Production data'!AD5 -> 740 | DP11: =IF((DO11=0),0,DN11/DO11) -> 0.093243243 | DQ11: =DP11*9.04 -> 0.84291892 | DR11: 79 | DS11: ='Production data'!AE5 -> 340 | DT11: =IF((DS11=0),0,DR11/DS11) -> 0.23235294 | DU11: =DT11*9.04 -> 2.1004706 | DW11: ='Production data'!AF5 -> 0 | DX11: =IF((DW11=0),0,DV11/DW11) -> 0 | DY11: =DX11*9.04 -> 0 | DZ11: =F11+J11+N11+R11+V11+Z11+AD11+AH11+AL11+AP11+AT11+AX11+BB11+BF11+BJ11+BN11+BR11+BV11+BZ11+CD11+CH11+CL11+CP11+CT11+CX11+DB11+DF11+DJ11+DN11+DR11+DV11 -> 1410 | EA11: =G11+K11+O11+S11+W11+AA11+AI11+AM11+AQ11+AU11+AY11+BC11+BG11+BK11+BO11+BS11+BW11+CA11+CE11+CI11+CM11+CQ11+CU11+CY11+DC11+DG11+DK11+DO11+DS11+DW11 -> 12230 | EB11: =IF((EA11=0),0,DZ11/EA11) -> 0.11529027 | EC11: =EB11*9.04 -> 1.042224
C12: 22 | D12: SHAFT UNO CNC 2 | F12: 0 | G12: =G11 -> 0 | H12: =IF((G12=0),0,F12/G12) -> 0 | I12: =H12*9.04 -> 0 | J12: 63 | K12: =K11 -> 623 | L12: =IF((K12=0),0,J12/K12) -> 0.1011236 | M12: =L12*9.04 -> 0.9141573 | N12: 34 | O12: =O11 -> 370 | P12: =IF((O12=0),0,N12/O12) -> 0.091891892 | Q12: =P12*9.04 -> 0.8307027 | R12: 62 | S12: =S11 -> 580 | T12: =IF((S12=0),0,R12/S12) -> 0.10689655 | U12: =T12*9.04 -> 0.96634483 | V12: 34 | W12: =W11 -> 300 | X12: =IF((W12=0),0,V12/W12) -> 0.11333333 | Y12: =X12*9.04 -> 1.0245333 | Z12: 0 | AA12: =AA11 -> 0 | AB12: =IF((AA12=0),0,Z12/AA12) -> 0 | AC12: =AB12*9.04 -> 0 | AD12: 47 | AE12: =AE11 -> 448 | AF12: =IF((AE12=0),0,AD12/AE12) -> 0.10491071 | AG12: =AF12*9.04 -> 0.94839286 | AH12: 39 | AI12: =AI11 -> 400 | AJ12: =IF((AI12=0),0,AH12/AI12) -> 0.0975 | AK12: =AJ12*9.04 -> 0.8814 | AL12: 46 | AM12: =AM11 -> 347 | AN12: =IF((AM12=0),0,AL12/AM12) -> 0.13256484 | AO12: =AN12*9.04 -> 1.1983862 | AP12: 62 | AQ12: =AQ11 -> 473 | AR12: =IF((AQ12=0),0,AP12/AQ12) -> 0.13107822 | AS12: =AR12*9.04 -> 1.1849471 | AT12: 56 | AU12: =AU11 -> 432 | AV12: =IF((AU12=0),0,AT12/AU12) -> 0.12962963 | AW12: =AV12*9.04 -> 1.1718519 | AX12: 61 | AY12: =AY11 -> 550 | AZ12: =IF((AY12=0),0,AX12/AY12) -> 0.11090909 | BA12: =AZ12*9.04 -> 1.0026182 | BB12: 69 | BC12: =BC11 -> 670 | BD12: =IF((BC12=0),0,BB12/BC12) -> 0.10298507 | BE12: =BD12*9.04 -> 0.93098507 | BF12: 30 | BG12: =BG11 -> 260 | BH12: =IF((BG12=0),0,BF12/BG12) -> 0.11538462 | BI12: =BH12*9.04 -> 1.0430769 | BJ12: 72 | BK12: =BK11 -> 711 | BL12: =IF((BK12=0),0,BJ12/BK12) -> 0.10126582 | BM12: =BL12*9.04 -> 0.91544304 | BN12: 70 | BO12: =BO11 -> 749 | BP12: =IF((BO12=0),0,BN12/BO12) -> 0.093457944 | BQ12: =BP12*9.04 -> 0.84485981 | BR12: 28 | BS12: =BS11 -> 192 | BT12: =IF((BS12=0),0,BR12/BS12) -> 0.14583333 | BU12: =BT12*9.04 -> 1.3183333 | BV12: 57 | BW12: =BW11 -> 560 | BX12: =IF((BW12=0),0,BV12/BW12) -> 0.10178571 | BY12: =BX12*9.04 -> 0.92014286 | BZ12: 77 | CA12: =CA11 -> 804 | CB12: =IF((CA12=0),0,BZ12/CA12) -> 0.095771144 | CC12: =CB12*9.04 -> 0.86577114 | CD12: 75 | CE12: =CE11 -> 821 | CF12: =IF((CE12=0),0,CD12/CE12) -> 0.09135201 | CG12: =CF12*9.04 -> 0.82582217 | CH12: 4 | CI12: =CI11 -> 0 | CJ12: =IF((CI12=0),0,CH12/CI12) -> 0 | CK12: =CJ12*9.04 -> 0 | CL12: 61 | CM12: =CM11 -> 635 | CN12: =IF((CM12=0),0,CL12/CM12) -> 0.096062992 | CO12: =CN12*9.04 -> 0.86840945 | CP12: 32 | CQ12: =CQ11 -> 271 | CR12: =IF((CQ12=0),0,CP12/CQ12) -> 0.11808118 | CS12: =CR12*9.04 -> 1.0674539 | CT12: 23 | CU12: =CU11 -> 150 | CV12: =IF((CU12=0),0,CT12/CU12) -> 0.15333333 | CW12: =CV12*9.04 -> 1.3861333 | CX12: 20 | CY12: =CY11 -> 130 | CZ12: =IF((CY12=0),0,CX12/CY12) -> 0.15384615 | DA12: =CZ12*9.04 -> 1.3907692 | DB12: 56 | DC12: =DC11 -> 442 | DD12: =IF((DC12=0),0,DB12/DC12) -> 0.12669683 | DE12: =DD12*9.04 -> 1.1453394 | DF12: 57 | DG12: =DG11 -> 550 | DH12: =IF((DG12=0),0,DF12/DG12) -> 0.10363636 | DI12: =DH12*9.04 -> 0.93687273 | DJ12: 25 | DK12: =DK11 -> 130 | DL12: =IF((DK12=0),0,DJ12/DK12) -> 0.19230769 | DM12: =DL12*9.04 -> 1.7384615 | DN12: 70 | DO12: =DO11 -> 740 | DP12: =IF((DO12=0),0,DN12/DO12) -> 0.094594595 | DQ12: =DP12*9.04 -> 0.85513514 | DR12: 0 | DS12: =DS11 -> 340 | DT12: =IF((DS12=0),0,DR12/DS12) -> 0 | DU12: =DT12*9.04 -> 0 | DW12: =DW11 -> 0 | DX12: =IF((DW12=0),0,DV12/DW12) -> 0 | DY12: =DX12*9.04 -> 0 | DZ12: =F12+J12+N12+R12+V12+Z12+AD12+AH12+AL12+AP12+AT12+AX12+BB12+BF12+BJ12+BN12+BR12+BV12+BZ12+CD12+CH12+CL12+CP12+CT12+CX12+DB12+DF12+DJ12+DN12+DR12+DV12 -> 1330 | EA12: =G12+K12+O12+S12+W12+AA12+AI12+AM12+AQ12+AU12+AY12+BC12+BG12+BK12+BO12+BS12+BW12+CA12+CE12+CI12+CM12+CQ12+CU12+CY12+DC12+DG12+DK12+DO12+DS12+DW12 -> 12230 | EB12: =IF((EA12=0),0,DZ12/EA12) -> 0.10874898 | EC12: =EB12*9.04 -> 0.98309076
C13: 23 | D13: SHAFT RACK ROLLING | F13: 0 | G13: ='Production data'!B16 -> 0 | H13: =IF((G13=0),0,F13/G13) -> 0 | I13: =H13*9.04 -> 0 | J13: 74 | K13: ='Production data'!C16 -> 1159 | L13: =IF((K13=0),0,J13/K13) -> 0.063848145 | M13: =L13*9.04 -> 0.57718723 | N13: 62 | O13: ='Production data'!D16 -> 918 | P13: =IF((O13=0),0,N13/O13) -> 0.067538126 | Q13: =P13*9.04 -> 0.61054466 | R13: 72 | S13: ='Production data'!E16 -> 1274 | T13: =IF((S13=0),0,R13/S13) -> 0.056514914 | U13: =T13*9.04 -> 0.51089482 | V13: 68 | W13: ='Production data'!F16 -> 1216 | X13: =IF((W13=0),0,V13/W13) -> 0.055921053 | Y13: =X13*9.04 -> 0.50552632 | Z13: 1 | AA13: ='Production data'!G16 -> 0 | AB13: =IF((AA13=0),0,Z13/AA13) -> 0 | AC13: =AB13*9.04 -> 0 | AD13: 65 | AE13: ='Production data'!H16 -> 1170 | AF13: =IF((AE13=0),0,AD13/AE13) -> 0.055555556 | AG13: =AF13*9.04 -> 0.50222222 | AH13: 69 | AI13: ='Production data'!I16 -> 1055 | AJ13: =IF((AI13=0),0,AH13/AI13) -> 0.065402844 | AK13: =AJ13*9.04 -> 0.59124171 | AL13: 58 | AM13: ='Production data'!J16 -> 567 | AN13: =IF((AM13=0),0,AL13/AM13) -> 0.10229277 | AO13: =AN13*9.04 -> 0.92472663 | AP13: 57 | AQ13: ='Production data'!K16 -> 589 | AR13: =IF((AQ13=0),0,AP13/AQ13) -> 0.096774194 | AS13: =AR13*9.04 -> 0.87483871 | AT13: 63 | AU13: ='Production data'!L16 -> 800 | AV13: =IF((AU13=0),0,AT13/AU13) -> 0.07875 | AW13: =AV13*9.04 -> 0.7119 | AX13: 57 | AY13: ='Production data'!M16 -> 555 | AZ13: =IF((AY13=0),0,AX13/AY13) -> 0.1027027 | BA13: =AZ13*9.04 -> 0.92843243 | BB13: 66 | BC13: ='Production data'!N16 -> 858 | BD13: =IF((BC13=0),0,BB13/BC13) -> 0.076923077 | BE13: =BD13*9.04 -> 0.69538462 | BF13: 33 | BG13: ='Production data'!O16 -> 512 | BH13: =IF((BG13=0),0,BF13/BG13) -> 0.064453125 | BI13: =BH13*9.04 -> 0.58265625 | BJ13: 60 | BK13: ='Production data'!P16 -> 632 | BL13: =IF((BK13=0),0,BJ13/BK13) -> 0.094936709 | BM13: =BL13*9.04 -> 0.85822785 | BN13: 73 | BO13: ='Production data'!Q16 -> 1264 | BP13: =IF((BO13=0),0,BN13/BO13) -> 0.057753165 | BQ13: =BP13*9.04 -> 0.52208861 | BR13: 65 | BS13: ='Production data'!R16 -> 1055 | BT13: =IF((BS13=0),0,BR13/BS13) -> 0.061611374 | BU13: =BT13*9.04 -> 0.55696682 | BV13: 65 | BW13: ='Production data'!S16 -> 850 | BX13: =IF((BW13=0),0,BV13/BW13) -> 0.076470588 | BY13: =BX13*9.04 -> 0.69129412 | BZ13: 76 | CA13: ='Production data'!T16 -> 960 | CB13: =IF((CA13=0),0,BZ13/CA13) -> 0.079166667 | CC13: =CB13*9.04 -> 0.71566667 | CD13: 69 | CE13: ='Production data'!U16 -> 440 | CF13: =IF((CE13=0),0,CD13/CE13) -> 0.15681818 | CG13: =CF13*9.04 -> 1.4176364 | CH13: 2 | CI13: ='Production data'!V16 -> 0 | CJ13: =IF((CI13=0),0,CH13/CI13) -> 0 | CK13: =CJ13*9.04 -> 0 | CL13: 72 | CM13: ='Production data'!W16 -> 1236 | CN13: =IF((CM13=0),0,CL13/CM13) -> 0.058252427 | CO13: =CN13*9.04 -> 0.52660194 | CP13: 69 | CQ13: ='Production data'!X16 -> 841 | CR13: =IF((CQ13=0),0,CP13/CQ13) -> 0.082045184 | CS13: =CR13*9.04 -> 0.74168847 | CT13: 63 | CU13: ='Production data'!Y16 -> 791 | CV13: =IF((CU13=0),0,CT13/CU13) -> 0.079646018 | CW13: =CV13*9.04 -> 0.72 | CX13: 55 | CY13: ='Production data'!Z16 -> 568 | CZ13: =IF((CY13=0),0,CX13/CY13) -> 0.096830986 | DA13: =CZ13*9.04 -> 0.87535211 | DB13: 63 | DC13: ='Production data'!AA16 -> 846 | DD13: =IF((DC13=0),0,DB13/DC13) -> 0.074468085 | DE13: =DD13*9.04 -> 0.67319149 | DF13: 68 | DG13: ='Production data'!AB16 -> 710 | DH13: =IF((DG13=0),0,DF13/DG13) -> 0.095774648 | DI13: =DH13*9.04 -> 0.86580282 | DJ13: 52 | DK13: ='Production data'!AC16 -> 936 | DL13: =IF((DK13=0),0,DJ13/DK13) -> 0.055555556 | DM13: =DL13*9.04 -> 0.50222222 | DN13: 88 | DO13: ='Production data'!AD16 -> 617 | DP13: =IF((DO13=0),0,DN13/DO13) -> 0.14262561 | DQ13: =DP13*9.04 -> 1.2893355 | DR13: 58 | DS13: ='Production data'!AE16 -> 692 | DT13: =IF((DS13=0),0,DR13/DS13) -> 0.083815029 | DU13: =DT13*9.04 -> 0.75768786 | DW13: ='Production data'!AF16 -> 0 | DX13: =IF((DW13=0),0,DV13/DW13) -> 0 | DY13: =DX13*9.04 -> 0 | DZ13: =F13+J13+N13+R13+V13+Z13+AD13+AH13+AL13+AP13+AT13+AX13+BB13+BF13+BJ13+BN13+BR13+BV13+BZ13+CD13+CH13+CL13+CP13+CT13+CX13+DB13+DF13+DJ13+DN13+DR13+DV13 -> 1743 | EA13: =G13+K13+O13+S13+W13+AA13+AI13+AM13+AQ13+AU13+AY13+BC13+BG13+BK13+BO13+BS13+BW13+CA13+CE13+CI13+CM13+CQ13+CU13+CY13+DC13+DG13+DK13+DO13+DS13+DW13 -> 21941 | EB13: =IF((EA13=0),0,DZ13/EA13) -> 0.079440317 | EC13: =EB13*9.04 -> 0.71814047
C14: 24 | D14: SHAFT ROBO 892 | F14: 0 | G14: =G12 -> 0 | H14: =IF((G14=0),0,F14/G14) -> 0 | I14: =H14*9.04 -> 0 | J14: 15 | K14: =K12 -> 623 | L14: =IF((K14=0),0,J14/K14) -> 0.024077047 | M14: =L14*9.04 -> 0.2176565 | N14: 12 | O14: =O12 -> 370 | P14: =IF((O14=0),0,N14/O14) -> 0.032432432 | Q14: =P14*9.04 -> 0.29318919 | R14: 13 | S14: =S12 -> 580 | T14: =IF((S14=0),0,R14/S14) -> 0.022413793 | U14: =T14*9.04 -> 0.20262069 | V14: 12 | W14: =W12 -> 300 | X14: =IF((W14=0),0,V14/W14) -> 0.04 | Y14: =X14*9.04 -> 0.3616 | Z14: 0 | AA14: =AA12 -> 0 | AB14: =IF((AA14=0),0,Z14/AA14) -> 0 | AC14: =AB14*9.04 -> 0 | AD14: 5 | AE14: =AE12 -> 448 | AF14: =IF((AE14=0),0,AD14/AE14) -> 0.011160714 | AG14: =AF14*9.04 -> 0.10089286 | AH14: 15 | AI14: =AI12 -> 400 | AJ14: =IF((AI14=0),0,AH14/AI14) -> 0.0375 | AK14: =AJ14*9.04 -> 0.339 | AL14: 12 | AM14: =AM12 -> 347 | AN14: =IF((AM14=0),0,AL14/AM14) -> 0.034582133 | AO14: =AN14*9.04 -> 0.31262248 | AP14: 12 | AQ14: =AQ12 -> 473 | AR14: =IF((AQ14=0),0,AP14/AQ14) -> 0.025369979 | AS14: =AR14*9.04 -> 0.22934461 | AT14: 13 | AU14: =AU12 -> 432 | AV14: =IF((AU14=0),0,AT14/AU14) -> 0.030092593 | AW14: =AV14*9.04 -> 0.27203704 | AX14: 12 | AY14: =AY12 -> 550 | AZ14: =IF((AY14=0),0,AX14/AY14) -> 0.021818182 | BA14: =AZ14*9.04 -> 0.19723636 | BB14: 17 | BC14: =BC12 -> 670 | BD14: =IF((BC14=0),0,BB14/BC14) -> 0.025373134 | BE14: =BD14*9.04 -> 0.22937313 | BF14: 8 | BG14: =BG12 -> 260 | BH14: =IF((BG14=0),0,BF14/BG14) -> 0.030769231 | BI14: =BH14*9.04 -> 0.27815385 | BJ14: 11 | BK14: =BK12 -> 711 | BL14: =IF((BK14=0),0,BJ14/BK14) -> 0.015471167 | BM14: =BL14*9.04 -> 0.13985935 | BN14: 16 | BO14: =BO12 -> 749 | BP14: =IF((BO14=0),0,BN14/BO14) -> 0.021361816 | BQ14: =BP14*9.04 -> 0.19311081 | BR14: 14 | BS14: =BS12 -> 192 | BT14: =IF((BS14=0),0,BR14/BS14) -> 0.072916667 | BU14: =BT14*9.04 -> 0.65916667 | BV14: 14 | BW14: =BW12 -> 560 | BX14: =IF((BW14=0),0,BV14/BW14) -> 0.025 | BY14: =BX14*9.04 -> 0.226 | BZ14: 17 | CA14: =CA12 -> 804 | CB14: =IF((CA14=0),0,BZ14/CA14) -> 0.021144279 | CC14: =CB14*9.04 -> 0.19114428 | CD14: 11 | CE14: =CE12 -> 821 | CF14: =IF((CE14=0),0,CD14/CE14) -> 0.013398295 | CG14: =CF14*9.04 -> 0.12112058 | CH14: 0 | CI14: =CI12 -> 0 | CJ14: =IF((CI14=0),0,CH14/CI14) -> 0 | CK14: =CJ14*9.04 -> 0 | CL14: 12 | CM14: =CM12 -> 635 | CN14: =IF((CM14=0),0,CL14/CM14) -> 0.018897638 | CO14: =CN14*9.04 -> 0.17083465 | CP14: 13 | CQ14: =CQ12 -> 271 | CR14: =IF((CQ14=0),0,CP14/CQ14) -> 0.04797048 | CS14: =CR14*9.04 -> 0.43365314 | CT14: 16 | CU14: =CU12 -> 150 | CV14: =IF((CU14=0),0,CT14/CU14) -> 0.10666667 | CW14: =CV14*9.04 -> 0.96426667 | CX14: 12 | CY14: =CY12 -> 130 | CZ14: =IF((CY14=0),0,CX14/CY14) -> 0.092307692 | DA14: =CZ14*9.04 -> 0.83446154 | DB14: 11 | DC14: =DC12 -> 442 | DD14: =IF((DC14=0),0,DB14/DC14) -> 0.024886878 | DE14: =DD14*9.04 -> 0.22497738 | DF14: 15 | DG14: =DG12 -> 550 | DH14: =IF((DG14=0),0,DF14/DG14) -> 0.027272727 | DI14: =DH14*9.04 -> 0.24654545 | DJ14: 10 | DK14: =DK12 -> 130 | DL14: =IF((DK14=0),0,DJ14/DK14) -> 0.076923077 | DM14: =DL14*9.04 -> 0.69538462 | DN14: 16 | DO14: =DO12 -> 740 | DP14: =IF((DO14=0),0,DN14/DO14) -> 0.021621622 | DQ14: =DP14*9.04 -> 0.19545946 | DR14: 11 | DS14: =DS12 -> 340 | DT14: =IF((DS14=0),0,DR14/DS14) -> 0.032352941 | DU14: =DT14*9.04 -> 0.29247059 | DW14: =DW12 -> 0 | DX14: =IF((DW14=0),0,DV14/DW14) -> 0 | DY14: =DX14*9.04 -> 0 | DZ14: =F14+J14+N14+R14+V14+Z14+AD14+AH14+AL14+AP14+AT14+AX14+BB14+BF14+BJ14+BN14+BR14+BV14+BZ14+CD14+CH14+CL14+CP14+CT14+CX14+DB14+DF14+DJ14+DN14+DR14+DV14 -> 345 | EA14: =G14+K14+O14+S14+W14+AA14+AI14+AM14+AQ14+AU14+AY14+BC14+BG14+BK14+BO14+BS14+BW14+CA14+CE14+CI14+CM14+CQ14+CU14+CY14+DC14+DG14+DK14+DO14+DS14+DW14 -> 12230 | EB14: =IF((EA14=0),0,DZ14/EA14) -> 0.028209321 | EC14: =EB14*9.04 -> 0.25501226
C15: 25 | D15: SHAFT WASHING MACHINE | F15: 0 | G15: =G14 -> 0 | H15: =IF((G15=0),0,F15/G15) -> 0 | I15: =H15*9.04 -> 0 | J15: 9 | K15: =K14 -> 623 | L15: =IF((K15=0),0,J15/K15) -> 0.014446228 | M15: =L15*9.04 -> 0.1305939 | N15: 14 | O15: =O14 -> 370 | P15: =IF((O15=0),0,N15/O15) -> 0.037837838 | Q15: =P15*9.04 -> 0.34205405 | R15: 13 | S15: =S14 -> 580 | T15: =IF((S15=0),0,R15/S15) -> 0.022413793 | U15: =T15*9.04 -> 0.20262069 | V15: 12 | W15: =W14 -> 300 | X15: =IF((W15=0),0,V15/W15) -> 0.04 | Y15: =X15*9.04 -> 0.3616 | Z15: 0 | AA15: =AA14 -> 0 | AB15: =IF((AA15=0),0,Z15/AA15) -> 0 | AC15: =AB15*9.04 -> 0 | AD15: 6 | AE15: =AE14 -> 448 | AF15: =IF((AE15=0),0,AD15/AE15) -> 0.013392857 | AG15: =AF15*9.04 -> 0.12107143 | AH15: 16 | AI15: =AI14 -> 400 | AJ15: =IF((AI15=0),0,AH15/AI15) -> 0.04 | AK15: =AJ15*9.04 -> 0.3616 | AL15: 10 | AM15: =AM14 -> 347 | AN15: =IF((AM15=0),0,AL15/AM15) -> 0.028818444 | AO15: =AN15*9.04 -> 0.26051873 | AP15: 7 | AQ15: =AQ14 -> 473 | AR15: =IF((AQ15=0),0,AP15/AQ15) -> 0.014799154 | AS15: =AR15*9.04 -> 0.13378436 | AT15: 14 | AU15: =AU14 -> 432 | AV15: =IF((AU15=0),0,AT15/AU15) -> 0.032407407 | AW15: =AV15*9.04 -> 0.29296296 | AX15: 13 | AY15: =AY14 -> 550 | AZ15: =IF((AY15=0),0,AX15/AY15) -> 0.023636364 | BA15: =AZ15*9.04 -> 0.21367273 | BB15: 24 | BC15: =BC14 -> 670 | BD15: =IF((BC15=0),0,BB15/BC15) -> 0.035820896 | BE15: =BD15*9.04 -> 0.3238209 | BF15: 7 | BG15: =BG14 -> 260 | BH15: =IF((BG15=0),0,BF15/BG15) -> 0.026923077 | BI15: =BH15*9.04 -> 0.24338462 | BJ15: 12 | BK15: =BK14 -> 711 | BL15: =IF((BK15=0),0,BJ15/BK15) -> 0.016877637 | BM15: =BL15*9.04 -> 0.15257384 | BN15: 25 | BO15: =BO14 -> 749 | BP15: =IF((BO15=0),0,BN15/BO15) -> 0.033377837 | BQ15: =BP15*9.04 -> 0.30173565 | BR15: 7 | BS15: =BS14 -> 192 | BT15: =IF((BS15=0),0,BR15/BS15) -> 0.036458333 | BU15: =BT15*9.04 -> 0.32958333 | BV15: 10 | BW15: =BW14 -> 560 | BX15: =IF((BW15=0),0,BV15/BW15) -> 0.017857143 | BY15: =BX15*9.04 -> 0.16142857 | BZ15: 19 | CA15: =CA14 -> 804 | CB15: =IF((CA15=0),0,BZ15/CA15) -> 0.023631841 | CC15: =CB15*9.04 -> 0.21363184 | CD15: 3 | CE15: =CE14 -> 821 | CF15: =IF((CE15=0),0,CD15/CE15) -> 0.0036540804 | CG15: =CF15*9.04 -> 0.033032887 | CH15: 0 | CI15: =CI14 -> 0 | CJ15: =IF((CI15=0),0,CH15/CI15) -> 0 | CK15: =CJ15*9.04 -> 0 | CL15: 16 | CM15: =CM14 -> 635 | CN15: =IF((CM15=0),0,CL15/CM15) -> 0.02519685 | CO15: =CN15*9.04 -> 0.22777953 | CP15: 5 | CQ15: =CQ14 -> 271 | CR15: =IF((CQ15=0),0,CP15/CQ15) -> 0.018450185 | CS15: =CR15*9.04 -> 0.16678967 | CT15: 14 | CU15: =CU14 -> 150 | CV15: =IF((CU15=0),0,CT15/CU15) -> 0.093333333 | CW15: =CV15*9.04 -> 0.84373333 | CX15: 6 | CY15: =CY14 -> 130 | CZ15: =IF((CY15=0),0,CX15/CY15) -> 0.046153846 | DA15: =CZ15*9.04 -> 0.41723077 | DB15: 4 | DC15: =DC14 -> 442 | DD15: =IF((DC15=0),0,DB15/DC15) -> 0.0090497738 | DE15: =DD15*9.04 -> 0.081809955 | DF15: 10 | DG15: =DG14 -> 550 | DH15: =IF((DG15=0),0,DF15/DG15) -> 0.018181818 | DI15: =DH15*9.04 -> 0.16436364 | DJ15: 9 | DK15: =DK14 -> 130 | DL15: =IF((DK15=0),0,DJ15/DK15) -> 0.069230769 | DM15: =DL15*9.04 -> 0.62584615 | DN15: 10 | DO15: =DO14 -> 740 | DP15: =IF((DO15=0),0,DN15/DO15) -> 0.013513514 | DQ15: =DP15*9.04 -> 0.12216216 | DR15: 18 | DS15: =DS14 -> 340 | DT15: =IF((DS15=0),0,DR15/DS15) -> 0.052941176 | DU15: =DT15*9.04 -> 0.47858824 | DW15: =DW14 -> 0 | DX15: =IF((DW15=0),0,DV15/DW15) -> 0 | DY15: =DX15*9.04 -> 0 | DZ15: =F15+J15+N15+R15+V15+Z15+AD15+AH15+AL15+AP15+AT15+AX15+BB15+BF15+BJ15+BN15+BR15+BV15+BZ15+CD15+CH15+CL15+CP15+CT15+CX15+DB15+DF15+DJ15+DN15+DR15+DV15 -> 313 | EA15: =G15+K15+O15+S15+W15+AA15+AI15+AM15+AQ15+AU15+AY15+BC15+BG15+BK15+BO15+BS15+BW15+CA15+CE15+CI15+CM15+CQ15+CU15+CY15+DC15+DG15+DK15+DO15+DS15+DW15 -> 12230 | EB15: =IF((EA15=0),0,DZ15/EA15) -> 0.025592805 | EC15: =EB15*9.04 -> 0.23135895
C16: 26 | D16: SHAFT ROBO 891 | F16: 0 | G16: =G15 -> 0 | H16: =IF((G16=0),0,F16/G16) -> 0 | I16: =H16*9.04 -> 0 | J16: 0 | K16: =K15 -> 623 | L16: =IF((K16=0),0,J16/K16) -> 0 | M16: =L16*9.04 -> 0 | N16: 0 | O16: =O15 -> 370 | P16: =IF((O16=0),0,N16/O16) -> 0 | Q16: =P16*9.04 -> 0 | R16: 5 | S16: =S15 -> 580 | T16: =IF((S16=0),0,R16/S16) -> 0.0086206897 | U16: =T16*9.04 -> 0.077931034 | V16: 8 | W16: =W15 -> 300 | X16: =IF((W16=0),0,V16/W16) -> 0.026666667 | Y16: =X16*9.04 -> 0.24106667 | Z16: 0 | AA16: =AA15 -> 0 | AB16: =IF((AA16=0),0,Z16/AA16) -> 0 | AC16: =AB16*9.04 -> 0 | AD16: 0 | AE16: =AE15 -> 448 | AF16: =IF((AE16=0),0,AD16/AE16) -> 0 | AG16: =AF16*9.04 -> 0 | AH16: 0 | AI16: =AI15 -> 400 | AJ16: =IF((AI16=0),0,AH16/AI16) -> 0 | AK16: =AJ16*9.04 -> 0 | AL16: 5 | AM16: =AM15 -> 347 | AN16: =IF((AM16=0),0,AL16/AM16) -> 0.014409222 | AO16: =AN16*9.04 -> 0.13025937 | AP16: 8 | AQ16: =AQ15 -> 473 | AR16: =IF((AQ16=0),0,AP16/AQ16) -> 0.016913319 | AS16: =AR16*9.04 -> 0.15289641 | AT16: 8 | AU16: =AU15 -> 432 | AV16: =IF((AU16=0),0,AT16/AU16) -> 0.018518519 | AW16: =AV16*9.04 -> 0.16740741 | AX16: 0 | AY16: =AY15 -> 550 | AZ16: =IF((AY16=0),0,AX16/AY16) -> 0 | BA16: =AZ16*9.04 -> 0 | BB16: 16 | BC16: =BC15 -> 670 | BD16: =IF((BC16=0),0,BB16/BC16) -> 0.023880597 | BE16: =BD16*9.04 -> 0.2158806 | BF16: 2 | BG16: =BG15 -> 260 | BH16: =IF((BG16=0),0,BF16/BG16) -> 0.0076923077 | BI16: =BH16*9.04 -> 0.069538462 | BJ16: 9 | BK16: =BK15 -> 711 | BL16: =IF((BK16=0),0,BJ16/BK16) -> 0.012658228 | BM16: =BL16*9.04 -> 0.11443038 | BN16: 8 | BO16: =BO15 -> 749 | BP16: =IF((BO16=0),0,BN16/BO16) -> 0.010680908 | BQ16: =BP16*9.04 -> 0.096555407 | BR16: 7 | BS16: =BS15 -> 192 | BT16: =IF((BS16=0),0,BR16/BS16) -> 0.036458333 | BU16: =BT16*9.04 -> 0.32958333 | BV16: 8 | BW16: =BW15 -> 560 | BX16: =IF((BW16=0),0,BV16/BW16) -> 0.014285714 | BY16: =BX16*9.04 -> 0.12914286 | BZ16: 8 | CA16: =CA15 -> 804 | CB16: =IF((CA16=0),0,BZ16/CA16) -> 0.0099502488 | CC16: =CB16*9.04 -> 0.089950249 | CD16: 8 | CE16: =CE15 -> 821 | CF16: =IF((CE16=0),0,CD16/CE16) -> 0.0097442144 | CG16: =CF16*9.04 -> 0.088087698 | CH16: 0 | CI16: =CI15 -> 0 | CJ16: =IF((CI16=0),0,CH16/CI16) -> 0 | CK16: =CJ16*9.04 -> 0 | CL16: 7 | CM16: =CM15 -> 635 | CN16: =IF((CM16=0),0,CL16/CM16) -> 0.011023622 | CO16: =CN16*9.04 -> 0.099653543 | CP16: 8 | CQ16: =CQ15 -> 271 | CR16: =IF((CQ16=0),0,CP16/CQ16) -> 0.029520295 | CS16: =CR16*9.04 -> 0.26686347 | CT16: 8 | CU16: =CU15 -> 150 | CV16: =IF((CU16=0),0,CT16/CU16) -> 0.053333333 | CW16: =CV16*9.04 -> 0.48213333 | CX16: 7 | CY16: =CY15 -> 130 | CZ16: =IF((CY16=0),0,CX16/CY16) -> 0.053846154 | DA16: =CZ16*9.04 -> 0.48676923 | DB16: 8 | DC16: =DC15 -> 442 | DD16: =IF((DC16=0),0,DB16/DC16) -> 0.018099548 | DE16: =DD16*9.04 -> 0.16361991 | DF16: 8 | DG16: =DG15 -> 550 | DH16: =IF((DG16=0),0,DF16/DG16) -> 0.014545455 | DI16: =DH16*9.04 -> 0.13149091 | DJ16: 2 | DK16: =DK15 -> 130 | DL16: =IF((DK16=0),0,DJ16/DK16) -> 0.015384615 | DM16: =DL16*9.04 -> 0.13907692 | DN16: 8 | DO16: =DO15 -> 740 | DP16: =IF((DO16=0),0,DN16/DO16) -> 0.010810811 | DQ16: =DP16*9.04 -> 0.09772973 | DR16: 13 | DS16: =DS15 -> 340 | DT16: =IF((DS16=0),0,DR16/DS16) -> 0.038235294 | DU16: =DT16*9.04 -> 0.34564706 | DW16: =DW15 -> 0 | DX16: =IF((DW16=0),0,DV16/DW16) -> 0 | DY16: =DX16*9.04 -> 0 | DZ16: =F16+J16+N16+R16+V16+Z16+AD16+AH16+AL16+AP16+AT16+AX16+BB16+BF16+BJ16+BN16+BR16+BV16+BZ16+CD16+CH16+CL16+CP16+CT16+CX16+DB16+DF16+DJ16+DN16+DR16+DV16 -> 169 | EA16: =G16+K16+O16+S16+W16+AA16+AI16+AM16+AQ16+AU16+AY16+BC16+BG16+BK16+BO16+BS16+BW16+CA16+CE16+CI16+CM16+CQ16+CU16+CY16+DC16+DG16+DK16+DO16+DS16+DW16 -> 12230 | EB16: =IF((EA16=0),0,DZ16/EA16) -> 0.013818479 | EC16: =EB16*9.04 -> 0.12491905
